Workbook

Sheet NDB検査件数評価
A1: 診療年月：2024年04月～2025年03月 D 検査 外来 ※集計結果が10未満の場合は「‐」で表示（10未満の箇所が1箇所の場合は10以上の最小値を全て「‐」で表示）※集計対象期間内に名称や点数・金額等に変更がある場合、変更後の情報で表示
A2: 診療年月：2024年04月～2025年03月 D 検査 入院 ※集計結果が10未満の場合は「‐」で表示（10未満の箇所が1箇所の場合は10以上の最小値を全て「‐」で表示）※集計対象期間内に名称や点数・金額等に変更がある場合、変更後の情報で表示
A4: 分類コード | B4: 分類名称 | C4: 診療行為コード | D4: 診療行為 | E4: 外来総計（算定回数） | F4: 入院総計（算定回数） | G4: 43+5項目 | H4: 確認用：外来診療行為コード | I4: 確認用：入院診療行為コード | J4: 不一致フラグ | K4: 電カル共有取り扱い項目 | L4: 黒川ダブルチェック | M4: 対応すると思われる電カル共有項目（FHIR項目名称） | N4: 材料違いだがの同種検査が43+5項目に含まれる | O4: 43+5項目に含まれる検査項目名（43+5項目での材料）
A5: D001 | B5: 尿中特殊物質定性定量検査 | C5: 160003750 | D5: Ｄｅａｎａｎｄ Ｂａｒｎｅｓ反応 | E5: - | F5: - | H5: Ｄｅａｎａｎｄ Ｂａｒｎｅｓ反応 | I5: Ｄｅａｎａｎｄ Ｂａｒｎｅｓ反応 | J5: ○ | L5: =IF([1]診療行為!G2=K5, "", "check")
A6: D001 | B6: 尿中特殊物質定性定量検査 | C6: 160156710 | D6: ポルフィリン症スクリーニングテスト（尿） | E6: - | F6: - | H6: ポルフィリン症スクリーニングテスト（尿） | I6: ポルフィリン症スクリーニングテスト（尿） | J6: ○ | L6: =IF([1]診療行為!G3=K6, "", "check")
A7: D003 | B7: 糞便検査 | C7: 160112610 | D7: ウロビリン（糞便） | E7: - | F7: - | H7: ウロビリン（糞便） | I7: ウロビリン（糞便） | J7: ○ | L7: =IF([1]診療行為!G4=K7, "", "check")
A8: D004-2 | B8: 悪性腫瘍組織検査 | C8: 160221910 | D8: 悪性腫瘍組織検査（処理が容易なもの）（その他のもの）（悪性黒色腫におけるセンチネルリンパ節生検に係る遺伝子検査） | E8: - | F8: - | H8: 悪性腫瘍組織検査（処理が容易なもの）（その他のもの）（悪性黒色腫におけるセンチネルリンパ節生検に係る遺伝子検査） | I8: 悪性腫瘍組織検査（処理が容易なもの）（その他のもの）（悪性黒色腫におけるセンチネルリンパ節生検に係る遺伝子検査） | J8: ○ | L8: =IF([1]診療行為!G5=K8, "", "check")
A9: D005 | B9: 血液形態・機能検査 | C9: 160228250 | D9: ＤＮＡ含有赤血球計数検査 | E9: - | F9: - | H9: ＤＮＡ含有赤血球計数検査 | I9: ＤＮＡ含有赤血球計数検査 | J9: ○ | L9: =IF([1]診療行為!G6=K9, "", "check")
A10: D006 | B10: 出血・凝固検査 | C10: 160012750 | D10: 蛇毒試験 | E10: - | F10: - | H10: 蛇毒試験 | I10: 蛇毒試験 | J10: ○ | L10: =IF([1]診療行為!G7=K10, "", "check")
A11: D006-4 | B11: 遺伝学的検査 | C11: 160239110 | D11: 遺伝学的検査（処理が複雑なもの）（複数疾患） | E11: - | F11: - | H11: 遺伝学的検査（処理が複雑なもの）（複数疾患） | I11: 遺伝学的検査（処理が複雑なもの）（複数疾患） | J11: ○ | L11: =IF([1]診療行為!G8=K11, "", "check")
A12: D006-4 | B12: 遺伝学的検査 | C12: 160239410 | D12: 遺伝学的検査（処理が複雑なもの）（（１）のエに掲げる遺伝子疾患の場合）（複数疾患） | E12: - | F12: - | H12: 遺伝学的検査（処理が複雑なもの）（（１）のエに掲げる遺伝子疾患の場合）（複数疾患） | I12: 遺伝学的検査（処理が複雑なもの）（（１）のエに掲げる遺伝子疾患の場合）（複数疾患） | J12: ○ | L12: =IF([1]診療行為!G9=K12, "", "check")
A13: D006-4 | B13: 遺伝学的検査 | C13: 160239510 | D13: 遺伝学的検査（処理が極めて複雑なもの）（（１）のエに掲げる遺伝子疾患の場合）（複数疾患） | E13: - | F13: - | H13: 遺伝学的検査（処理が極めて複雑なもの）（（１）のエに掲げる遺伝子疾患の場合）（複数疾患） | I13: 遺伝学的検査（処理が極めて複雑なもの）（（１）のエに掲げる遺伝子疾患の場合）（複数疾患） | J13: ○ | L13: =IF([1]診療行為!G10=K13, "", "check")
A14: D006-4 | B14: 遺伝学的検査 | C14: 160239710 | D14: 遺伝学的検査（処理が複雑なもの）（（１）のオに掲げる遺伝子疾患の場合）（複数疾患） | E14: - | F14: - | H14: 遺伝学的検査（処理が複雑なもの）（（１）のオに掲げる遺伝子疾患の場合）（複数疾患） | I14: 遺伝学的検査（処理が複雑なもの）（（１）のオに掲げる遺伝子疾患の場合）（複数疾患） | J14: ○ | L14: =IF([1]診療行為!G11=K14, "", "check")
A15: D006-4 | B15: 遺伝学的検査 | C15: 160239810 | D15: 遺伝学的検査（処理が極めて複雑なもの）（（１）のオに掲げる遺伝子疾患の場合）（複数疾患） | E15: - | F15: - | H15: 遺伝学的検査（処理が極めて複雑なもの）（（１）のオに掲げる遺伝子疾患の場合）（複数疾患） | I15: 遺伝学的検査（処理が極めて複雑なもの）（（１）のオに掲げる遺伝子疾患の場合）（複数疾患） | J15: ○ | L15: =IF([1]診療行為!G12=K15, "", "check")
A16: D006-27 | B16: 悪性腫瘍遺伝子検査（血液・血漿） | C16: 160223750 | D16: 悪性腫瘍遺伝子検査（血液・血漿）（ＭＥＴｅｘ１４遺伝子検査） | E16: - | F16: - | H16: 悪性腫瘍遺伝子検査（血液・血漿）（ＭＥＴｅｘ１４遺伝子検査） | I16: 悪性腫瘍遺伝子検査（血液・血漿）（ＭＥＴｅｘ１４遺伝子検査） | J16: ○ | L16: =IF([1]診療行為!G13=K16, "", "check")
... A19: D008 | B19: 内分泌学的検査 | C19: 160032110 | D19: セクレチン | E19: - | F19: - | H19: セクレチン | I19: セクレチン | J19: ○ | L19: =IF([1]診療行為!G16=K19, "", "check")
A20: D008 | B20: 内分泌学的検査 | C20: 160135950 | D20: １７－ケトジェニックステロイド（１７－ＫＧＳ）（尿） | E20: - | F20: - | H20: １７－ケトジェニックステロイド（１７－ＫＧＳ）（尿） | I20: １７－ケトジェニックステロイド（１７－ＫＧＳ）（尿） | J20: ○ | L20: =IF([1]診療行為!G18=K20, "", "check")
A21: D008 | B21: 内分泌学的検査 | C21: 160193210 | D21: エストロゲン定量（尿） | E21: - | F21: - | H21: エストロゲン定量（尿） | I21: エストロゲン定量（尿） | J21: ○ | L21: =IF([1]診療行為!G19=K21, "", "check")
A22: D009 | B22: 腫瘍マーカー | C22: 160184850 | D22: サイトケラチン８・１８（尿） | E22: - | F22: - | H22: サイトケラチン８・１８（尿） | I22: サイトケラチン８・１８（尿） | J22: ○ | L22: =IF([1]診療行為!G20=K22, "", "check")
A23: D010 | B23: 特殊分析 | C23: 160038750 | D23: フェニール・アラニン（血清） | E23: - | F23: - | H23: フェニール・アラニン（血清） | I23: フェニール・アラニン（血清） | J23: ○ | L23: =IF([1]診療行為!G21=K23, "", "check")
A24: D012 | B24: 感染症免疫学的検査 | C24: 160044810 | D24: ブルセラ抗体定性 | E24: - | F24: - | H24: ブルセラ抗体定性 | I24: ブルセラ抗体定性 | J24: ○ | L24: =IF([1]診療行為!G22=K24, "", "check")
A25: D012 | B25: 感染症免疫学的検査 | C25: 160143550 | D25: Ｄ－アラビニトール | E25: - | F25: - | H25: Ｄ－アラビニトール | I25: Ｄ－アラビニトール | J25: ○ | L25: =IF([1]診療行為!G23=K25, "", "check")
A26: D015 | B26: 血漿蛋白免疫学的検査 | C26: 160022710 | D26: グルコース－６－リン酸デヒドロゲナーゼ（Ｇ－６－ＰＤ）定性 | E26: - | F26: - | H26: グルコース－６－リン酸デヒドロゲナーゼ（Ｇ－６－ＰＤ）定性 | I26: グルコース－６－リン酸デヒドロゲナーゼ（Ｇ－６－ＰＤ）定性 | J26: ○ | L26: =IF([1]診療行為!G24=K26, "", "check")
A27: D210-2 | B27: 体表面心電図、心外膜興奮伝播図 | C27: 160069850 | D27: 心外膜興奮伝播図 | E27: - | F27: - | H27: 心外膜興奮伝播図 | I27: 心外膜興奮伝播図 | J27: ○ | L27: =IF([1]診療行為!G25=K27, "", "check")
A28: D236-2 | B28: 光トポグラフィー | C28: 160203510 | D28: 光トポグラフィー（抑うつ症状の鑑別診断の補助に使用するもの）（イ以外の場合） | E28: - | F28: - | H28: 光トポグラフィー（抑うつ症状の鑑別診断の補助に使用するもの）（イ以外の場合） | I28: 光トポグラフィー（抑うつ症状の鑑別診断の補助に使用するもの）（イ以外の場合） | J28: ○ | L28: =IF([1]診療行為!G26=K28, "", "check")
A29: D289 | B29: その他の機能テスト | C29: 160089150 | D29: アジスカウント（Ａｄｄｉｓ尿沈渣定量検査） | E29: - | F29: - | H29: アジスカウント（Ａｄｄｉｓ尿沈渣定量検査） | I29: アジスカウント（Ａｄｄｉｓ尿沈渣定量検査） | J29: ○ | L29: =IF([1]診療行為!G27=K29, "", "check")
A30: D289 | B30: その他の機能テスト | C30: 160089450 | D30: ヨードカリ試験 | E30: - | F30: - | H30: ヨードカリ試験 | I30: ヨードカリ試験 | J30: ○ | L30: =IF([1]診療行為!G28=K30, "", "check")
A31: D292 | B31: 体外からの計測によらない諸検査 | C31: 160090710 | D31: 血球量測定（ＲＩ） | E31: - | F31: - | H31: 血球量測定（ＲＩ） | I31: 血球量測定（ＲＩ） | J31: ○ | L31: =IF([1]診療行為!G29=K31, "", "check")
... A35: D417 | B35: 組織試験採取、切採法 | C35: 160100510 | D35: 組織試験採取、切採法（精巣上体（副睾丸）） | E35: - | F35: - | H35: 組織試験採取、切採法（精巣上体（副睾丸）） | I35: 組織試験採取、切採法（精巣上体（副睾丸）） | J35: ○ | L35: =IF([1]診療行為!G33=K35, "", "check")
A36: D226 | B36: 中心静脈圧測定 | C36: 160074410 | D36: 中心静脈圧測定（５回以上の場合）（１日につき） | E36: - | F36: 446039 | H36: 中心静脈圧測定（５回以上の場合）（１日につき） | I36: 中心静脈圧測定（５回以上の場合）（１日につき） | J36: ○ | L36: =IF([1]診療行為!G34=K36, "", "check")
A37: D235-3 | B37: 長期脳波ビデオ同時記録検査 | C37: 160207510 | D37: 長期脳波ビデオ同時記録検査１（１日につき） | E37: - | F37: 15577 | H37: 長期脳波ビデオ同時記録検査１（１日につき） | I37: 長期脳波ビデオ同時記録検査１（１日につき） | J37: ○ | L37: =IF([1]診療行為!G35=K37, "", "check")
A38: D227 | B38: 頭蓋内圧持続測定 | C38: 160103010 | D38: 頭蓋内圧持続測定（３時間を超えた場合）（１日につき） | E38: - | F38: 14584 | H38: 頭蓋内圧持続測定（３時間を超えた場合）（１日につき） | I38: 頭蓋内圧持続測定（３時間を超えた場合）（１日につき） | J38: ○ | L38: =IF([1]診療行為!G36=K38, "", "check")
A39: D417 | B39: 組織試験採取、切採法 | C39: 160188310 | D39: 組織試験採取、切採法（心筋） | E39: - | F39: 12911 | H39: 組織試験採取、切採法（心筋） | I39: 組織試験採取、切採法（心筋） | J39: ○ | L39: =IF([1]診療行為!G37=K39, "", "check")
A40: D006-21 | B40: 血液粘弾性検査 | C40: 160217410 | D40: 血液粘弾性検査（一連につき） | E40: - | F40: 6664 | H40: 血液粘弾性検査（一連につき） | I40: 血液粘弾性検査（一連につき） | J40: ○ | L40: =IF([1]診療行為!G38=K40, "", "check")
A41: D222 | B41: 経皮的血液ガス分圧測定、血液ガス連続測定 | C41: 160159450 | D41: 血液ガス連続測定（５時間を超えた場合）（１日につき） | E41: - | F41: 2939 | H41: 血液ガス連続測定（５時間を超えた場合）（１日につき） | I41: 血液ガス連続測定（５時間を超えた場合）（１日につき） | J41: ○ | L41: =IF([1]診療行為!G39=K41, "", "check")
A42: D303 | B42: 胸腔鏡検査 | C42: 160093010 | D42: 胸腔鏡検査 | E42: - | F42: 2070 | H42: 胸腔鏡検査 | I42: 胸腔鏡検査 | J42: ○ | L42: =IF([1]診療行為!G40=K42, "", "check")
A43: D004 | B43: 穿刺液・採取液検査 | C43: 160182110 | D43: マイクロバブルテスト | E43: - | F43: 1105 | H43: マイクロバブルテスト | I43: マイクロバブルテスト | J43: ○ | L43: =IF([1]診療行為!G41=K43, "", "check")
A44: D207 | B44: 体液量等測定 | C44: 160067610 | D44: 循環時間測定 | E44: - | F44: 645 | H44: 循環時間測定 | I44: 循環時間測定 | J44: ○ | L44: =IF([1]診療行為!G42=K44, "", "check")
A45: D314 | B45: 腹腔鏡検査 | C45: 160095010 | D45: 腹腔鏡検査 | E45: - | F45: 492 | H45: 腹腔鏡検査 | I45: 腹腔鏡検査 | J45: ○ | L45: =IF([1]診療行為!G43=K45, "", "check")
A46: D291-3 | B46: 内服・点滴誘発試験 | C46: 160187410 | D46: 内服・点滴誘発試験 | E46: - | F46: 435 | H46: 内服・点滴誘発試験 | I46: 内服・点滴誘発試験 | J46: ○ | L46: =IF([1]診療行為!G44=K46, "", "check")
...

Sheet 黒川作業＞

Sheet 電カル共有リスト
A1: 大項目 | B1: FHIR項目名称 | C1: FHIR識別文字列 | D1: 略称 | E1: 材料(JLAC11) | G1: ※JLACマスタにおいて大項目・FHIR項目名称・FHIR項目名称・材料の組み合わせで重複削除したリスト
A2: 総蛋白(TP) | B2: 総蛋白(TP) | C2: TP | D2: TP | E2: 血清
A3: 総蛋白(TP) | B3: 総蛋白(TP) | C3: TP | D3: TP | E3: 血漿
A4: 総蛋白(TP) | B4: 総蛋白(TP) | C4: TP | D4: TP | E4: 血漿(EDTA入り)
A5: 総蛋白(TP) | B5: 総蛋白(TP) | C5: TP | D5: TP | E5: 血漿(ヘパリン入り)
A6: 総蛋白(TP) | B6: 総蛋白(TP) | C6: TP | D6: TP | E6: 血漿(クエン酸入り)
A7: 総蛋白(TP) | B7: 総蛋白(TP) | C7: TP | D7: TP | E7: 血漿(フッ化物入り)
A8: 総蛋白(TP) | B8: 総蛋白(TP) | C8: TP | D8: TP | E8: 血漿(シュウ酸塩入り)
A9: 総蛋白(TP) | B9: 総蛋白(TP) | C9: TP | D9: TP
A10: アルブミン | B10: アルブミン | C10: ALB | D10: Alb | E10: 血清
A11: アルブミン | B11: アルブミン | C11: ALB | D11: Alb | E11: 血漿
A12: アルブミン | B12: アルブミン | C12: ALB | D12: Alb | E12: 血漿(ヘパリン入り)
A13: アルブミン | B13: アルブミン | C13: ALB | D13: Alb | E13: 血清(添加物入り)
A14: アルブミン | B14: アルブミン | C14: ALB | D14: Alb | E14: 血漿(EDTA入り)
A15: アルブミン | B15: アルブミン | C15: ALB | D15: Alb | E15: 血漿(クエン酸入り)
A16: アルブミン | B16: アルブミン | C16: ALB | D16: Alb | E16: 血漿(フッ化物入り)
A17: アルブミン | B17: アルブミン | C17: ALB | D17: Alb | E17: 血漿(シュウ酸塩入り)
A18: アルブミン | B18: アルブミン | C18: ALB | D18: Alb | E18: 血漿(添加物入り)
A19: アルブミン | B19: アルブミン | C19: ALB | D19: Alb | E19: 全血(静脈血)
A20: アルブミン | B20: アルブミン | C20: ALB | D20: Alb
A21: クレアチンキナーゼ(CK) | B21: クレアチンキナーゼ(CK) | C21: CK | D21: CK | E21: 血清
A22: クレアチンキナーゼ(CK) | B22: クレアチンキナーゼ(CK) | C22: CK | D22: CK | E22: 血漿
A23: クレアチンキナーゼ(CK) | B23: クレアチンキナーゼ(CK) | C23: CK | D23: CK | E23: 血漿(EDTA入り)
A24: クレアチンキナーゼ(CK) | B24: クレアチンキナーゼ(CK) | C24: CK | D24: CK | E24: 血清(添加物入り)
A25: クレアチンキナーゼ(CK) | B25: クレアチンキナーゼ(CK) | C25: CK | D25: CK | E25: 血漿(ヘパリン入り)
A26: クレアチンキナーゼ(CK) | B26: クレアチンキナーゼ(CK) | C26: CK | D26: CK | E26: 血漿(クエン酸入り)
A27: クレアチンキナーゼ(CK) | B27: クレアチンキナーゼ(CK) | C27: CK | D27: CK | E27: 血漿(フッ化物入り)
A28: クレアチンキナーゼ(CK) | B28: クレアチンキナーゼ(CK) | C28: CK | D28: CK | E28: 血漿(シュウ酸塩入り)
A29: クレアチンキナーゼ(CK) | B29: クレアチンキナーゼ(CK) | C29: CK | D29: CK | E29: 全血(静脈血、ヘパリン入り)
A30: クレアチンキナーゼ(CK) | B30: クレアチンキナーゼ(CK) | C30: CK | D30: CK
A31: AST(GOT) | B31: AST(GOT) | C31: AST | D31: AST | E31: 血清
A32: AST(GOT) | B32: AST(GOT) | C32: AST | D32: AST | E32: 血漿
A33: AST(GOT) | B33: AST(GOT) | C33: AST | D33: AST | E33: 血漿(ヘパリン入り)
A34: AST(GOT) | B34: AST(GOT) | C34: AST | D34: AST | E34: 血漿(EDTA入り)
A35: AST(GOT) | B35: AST(GOT) | C35: AST | D35: AST | E35: 血漿(クエン酸入り)
A36: AST(GOT) | B36: AST(GOT) | C36: AST | D36: AST | E36: 血漿(フッ化物入り)
A37: AST(GOT) | B37: AST(GOT) | C37: AST | D37: AST | E37: 血漿(シュウ酸塩入り)
A38: AST(GOT) | B38: AST(GOT) | C38: AST | D38: AST | E38: 全血(静脈血、ヘパリン入り)
A39: AST(GOT) | B39: AST(GOT) | C39: AST | D39: AST
A40: AST(GOT) | B40: AST(GOT) | C40: AST | D40: AST | E40: 全血(静脈血)
...

Sheet NDB項目が電カル共有に含まれるか
A1: 診療年月：2024年04月～2025年03月 D 検査 外来 ※集計結果が10未満の場合は「‐」で表示（10未満の箇所が1箇所の場合は10以上の最小値を全て「‐」で表示）※集計対象期間内に名称や点数・金額等に変更がある場合、変更後の情報で表示
A2: 診療年月：2024年04月～2025年03月 D 検査 入院 ※集計結果が10未満の場合は「‐」で表示（10未満の箇所が1箇所の場合は10以上の最小値を全て「‐」で表示）※集計対象期間内に名称や点数・金額等に変更がある場合、変更後の情報で表示
A4: 分類コード | B4: 分類名称 | C4: 診療行為コード | D4: 診療行為 | E4: 外来総計（算定回数） | F4: 入院総計（算定回数） | G4: 43+5項目 | H4: 確認用：外来診療行為コード | I4: 確認用：入院診療行為コード | J4: 不一致フラグ | K4: 電カル共有取り扱い項目 | L4: 黒川ダブルチェック | M4: 対応すると思われる電カル共有項目（FHIR項目名称）
A5: D001 | B5: 尿中特殊物質定性定量検査 | C5: 160003750 | D5: Ｄｅａｎａｎｄ Ｂａｒｎｅｓ反応 | E5: - | F5: - | H5: Ｄｅａｎａｎｄ Ｂａｒｎｅｓ反応 | I5: Ｄｅａｎａｎｄ Ｂａｒｎｅｓ反応 | J5: ○ | L5: =IF([1]診療行為!G2=K5, "", "check")
A6: D001 | B6: 尿中特殊物質定性定量検査 | C6: 160156710 | D6: ポルフィリン症スクリーニングテスト（尿） | E6: - | F6: - | H6: ポルフィリン症スクリーニングテスト（尿） | I6: ポルフィリン症スクリーニングテスト（尿） | J6: ○ | L6: =IF([1]診療行為!G3=K6, "", "check")
A7: D003 | B7: 糞便検査 | C7: 160112610 | D7: ウロビリン（糞便） | E7: - | F7: - | H7: ウロビリン（糞便） | I7: ウロビリン（糞便） | J7: ○ | L7: =IF([1]診療行為!G4=K7, "", "check")
A8: D004-2 | B8: 悪性腫瘍組織検査 | C8: 160221910 | D8: 悪性腫瘍組織検査（処理が容易なもの）（その他のもの）（悪性黒色腫におけるセンチネルリンパ節生検に係る遺伝子検査） | E8: - | F8: - | H8: 悪性腫瘍組織検査（処理が容易なもの）（その他のもの）（悪性黒色腫におけるセンチネルリンパ節生検に係る遺伝子検査） | I8: 悪性腫瘍組織検査（処理が容易なもの）（その他のもの）（悪性黒色腫におけるセンチネルリンパ節生検に係る遺伝子検査） | J8: ○ | L8: =IF([1]診療行為!G5=K8, "", "check")
A9: D005 | B9: 血液形態・機能検査 | C9: 160228250 | D9: ＤＮＡ含有赤血球計数検査 | E9: - | F9: - | H9: ＤＮＡ含有赤血球計数検査 | I9: ＤＮＡ含有赤血球計数検査 | J9: ○ | L9: =IF([1]診療行為!G6=K9, "", "check")
A10: D006 | B10: 出血・凝固検査 | C10: 160012750 | D10: 蛇毒試験 | E10: - | F10: - | H10: 蛇毒試験 | I10: 蛇毒試験 | J10: ○ | L10: =IF([1]診療行為!G7=K10, "", "check")
A11: D006-4 | B11: 遺伝学的検査 | C11: 160239110 | D11: 遺伝学的検査（処理が複雑なもの）（複数疾患） | E11: - | F11: - | H11: 遺伝学的検査（処理が複雑なもの）（複数疾患） | I11: 遺伝学的検査（処理が複雑なもの）（複数疾患） | J11: ○ | L11: =IF([1]診療行為!G8=K11, "", "check")
A12: D006-4 | B12: 遺伝学的検査 | C12: 160239410 | D12: 遺伝学的検査（処理が複雑なもの）（（１）のエに掲げる遺伝子疾患の場合）（複数疾患） | E12: - | F12: - | H12: 遺伝学的検査（処理が複雑なもの）（（１）のエに掲げる遺伝子疾患の場合）（複数疾患） | I12: 遺伝学的検査（処理が複雑なもの）（（１）のエに掲げる遺伝子疾患の場合）（複数疾患） | J12: ○ | L12: =IF([1]診療行為!G9=K12, "", "check")
A13: D006-4 | B13: 遺伝学的検査 | C13: 160239510 | D13: 遺伝学的検査（処理が極めて複雑なもの）（（１）のエに掲げる遺伝子疾患の場合）（複数疾患） | E13: - | F13: - | H13: 遺伝学的検査（処理が極めて複雑なもの）（（１）のエに掲げる遺伝子疾患の場合）（複数疾患） | I13: 遺伝学的検査（処理が極めて複雑なもの）（（１）のエに掲げる遺伝子疾患の場合）（複数疾患） | J13: ○ | L13: =IF([1]診療行為!G10=K13, "", "check")
A14: D006-4 | B14: 遺伝学的検査 | C14: 160239710 | D14: 遺伝学的検査（処理が複雑なもの）（（１）のオに掲げる遺伝子疾患の場合）（複数疾患） | E14: - | F14: - | H14: 遺伝学的検査（処理が複雑なもの）（（１）のオに掲げる遺伝子疾患の場合）（複数疾患） | I14: 遺伝学的検査（処理が複雑なもの）（（１）のオに掲げる遺伝子疾患の場合）（複数疾患） | J14: ○ | L14: =IF([1]診療行為!G11=K14, "", "check")
A15: D006-4 | B15: 遺伝学的検査 | C15: 160239810 | D15: 遺伝学的検査（処理が極めて複雑なもの）（（１）のオに掲げる遺伝子疾患の場合）（複数疾患） | E15: - | F15: - | H15: 遺伝学的検査（処理が極めて複雑なもの）（（１）のオに掲げる遺伝子疾患の場合）（複数疾患） | I15: 遺伝学的検査（処理が極めて複雑なもの）（（１）のオに掲げる遺伝子疾患の場合）（複数疾患） | J15: ○ | L15: =IF([1]診療行為!G12=K15, "", "check")
A16: D006-27 | B16: 悪性腫瘍遺伝子検査（血液・血漿） | C16: 160223750 | D16: 悪性腫瘍遺伝子検査（血液・血漿）（ＭＥＴｅｘ１４遺伝子検査） | E16: - | F16: - | H16: 悪性腫瘍遺伝子検査（血液・血漿）（ＭＥＴｅｘ１４遺伝子検査） | I16: 悪性腫瘍遺伝子検査（血液・血漿）（ＭＥＴｅｘ１４遺伝子検査） | J16: ○ | L16: =IF([1]診療行為!G13=K16, "", "check")
... A19: D008 | B19: 内分泌学的検査 | C19: 160032110 | D19: セクレチン | E19: - | F19: - | H19: セクレチン | I19: セクレチン | J19: ○ | L19: =IF([1]診療行為!G16=K19, "", "check")
A20: D400 | B20: 血液採取 | C20: 160095710 | D20: 血液採取（静脈） | E20: 182055444 | F20: 84255 | H20: 血液採取（静脈） | I20: 血液採取（静脈） | J20: ○ | L20: =IF([1]診療行為!G75=K20, "", "check")
A21: D008 | B21: 内分泌学的検査 | C21: 160135950 | D21: １７－ケトジェニックステロイド（１７－ＫＧＳ）（尿） | E21: - | F21: - | H21: １７－ケトジェニックステロイド（１７－ＫＧＳ）（尿） | I21: １７－ケトジェニックステロイド（１７－ＫＧＳ）（尿） | J21: ○ | L21: =IF([1]診療行為!G18=K21, "", "check")
A22: D008 | B22: 内分泌学的検査 | C22: 160193210 | D22: エストロゲン定量（尿） | E22: - | F22: - | H22: エストロゲン定量（尿） | I22: エストロゲン定量（尿） | J22: ○ | L22: =IF([1]診療行為!G19=K22, "", "check")
A23: D009 | B23: 腫瘍マーカー | C23: 160184850 | D23: サイトケラチン８・１８（尿） | E23: - | F23: - | H23: サイトケラチン８・１８（尿） | I23: サイトケラチン８・１８（尿） | J23: ○ | L23: =IF([1]診療行為!G20=K23, "", "check")
A24: D010 | B24: 特殊分析 | C24: 160038750 | D24: フェニール・アラニン（血清） | E24: - | F24: - | H24: フェニール・アラニン（血清） | I24: フェニール・アラニン（血清） | J24: ○ | L24: =IF([1]診療行為!G21=K24, "", "check")
A25: D012 | B25: 感染症免疫学的検査 | C25: 160044810 | D25: ブルセラ抗体定性 | E25: - | F25: - | H25: ブルセラ抗体定性 | I25: ブルセラ抗体定性 | J25: ○ | L25: =IF([1]診療行為!G22=K25, "", "check")
A26: D012 | B26: 感染症免疫学的検査 | C26: 160143550 | D26: Ｄ－アラビニトール | E26: - | F26: - | H26: Ｄ－アラビニトール | I26: Ｄ－アラビニトール | J26: ○ | L26: =IF([1]診療行為!G23=K26, "", "check")
A27: D015 | B27: 血漿蛋白免疫学的検査 | C27: 160022710 | D27: グルコース－６－リン酸デヒドロゲナーゼ（Ｇ－６－ＰＤ）定性 | E27: - | F27: - | H27: グルコース－６－リン酸デヒドロゲナーゼ（Ｇ－６－ＰＤ）定性 | I27: グルコース－６－リン酸デヒドロゲナーゼ（Ｇ－６－ＰＤ）定性 | J27: ○ | L27: =IF([1]診療行為!G24=K27, "", "check")
A28: D210-2 | B28: 体表面心電図、心外膜興奮伝播図 | C28: 160069850 | D28: 心外膜興奮伝播図 | E28: - | F28: - | H28: 心外膜興奮伝播図 | I28: 心外膜興奮伝播図 | J28: ○ | L28: =IF([1]診療行為!G25=K28, "", "check")
A29: D236-2 | B29: 光トポグラフィー | C29: 160203510 | D29: 光トポグラフィー（抑うつ症状の鑑別診断の補助に使用するもの）（イ以外の場合） | E29: - | F29: - | H29: 光トポグラフィー（抑うつ症状の鑑別診断の補助に使用するもの）（イ以外の場合） | I29: 光トポグラフィー（抑うつ症状の鑑別診断の補助に使用するもの）（イ以外の場合） | J29: ○ | L29: =IF([1]診療行為!G26=K29, "", "check")
A30: D289 | B30: その他の機能テスト | C30: 160089150 | D30: アジスカウント（Ａｄｄｉｓ尿沈渣定量検査） | E30: - | F30: - | H30: アジスカウント（Ａｄｄｉｓ尿沈渣定量検査） | I30: アジスカウント（Ａｄｄｉｓ尿沈渣定量検査） | J30: ○ | L30: =IF([1]診療行為!G27=K30, "", "check")
A31: D289 | B31: その他の機能テスト | C31: 160089450 | D31: ヨードカリ試験 | E31: - | F31: - | H31: ヨードカリ試験 | I31: ヨードカリ試験 | J31: ○ | L31: =IF([1]診療行為!G28=K31, "", "check")
A32: D292 | B32: 体外からの計測によらない諸検査 | C32: 160090710 | D32: 血球量測定（ＲＩ） | E32: - | F32: - | H32: 血球量測定（ＲＩ） | I32: 血球量測定（ＲＩ） | J32: ○ | L32: =IF([1]診療行為!G29=K32, "", "check")
... A36: D417 | B36: 組織試験採取、切採法 | C36: 160100510 | D36: 組織試験採取、切採法（精巣上体（副睾丸）） | E36: - | F36: - | H36: 組織試験採取、切採法（精巣上体（副睾丸）） | I36: 組織試験採取、切採法（精巣上体（副睾丸）） | J36: ○ | L36: =IF([1]診療行為!G33=K36, "", "check")
A37: D226 | B37: 中心静脈圧測定 | C37: 160074410 | D37: 中心静脈圧測定（５回以上の場合）（１日につき） | E37: - | F37: 446039 | H37: 中心静脈圧測定（５回以上の場合）（１日につき） | I37: 中心静脈圧測定（５回以上の場合）（１日につき） | J37: ○ | L37: =IF([1]診療行為!G34=K37, "", "check")
A38: D235-3 | B38: 長期脳波ビデオ同時記録検査 | C38: 160207510 | D38: 長期脳波ビデオ同時記録検査１（１日につき） | E38: - | F38: 15577 | H38: 長期脳波ビデオ同時記録検査１（１日につき） | I38: 長期脳波ビデオ同時記録検査１（１日につき） | J38: ○ | L38: =IF([1]診療行為!G35=K38, "", "check")
A39: D227 | B39: 頭蓋内圧持続測定 | C39: 160103010 | D39: 頭蓋内圧持続測定（３時間を超えた場合）（１日につき） | E39: - | F39: 14584 | H39: 頭蓋内圧持続測定（３時間を超えた場合）（１日につき） | I39: 頭蓋内圧持続測定（３時間を超えた場合）（１日につき） | J39: ○ | L39: =IF([1]診療行為!G36=K39, "", "check")
A40: D417 | B40: 組織試験採取、切採法 | C40: 160188310 | D40: 組織試験採取、切採法（心筋） | E40: - | F40: 12911 | H40: 組織試験採取、切採法（心筋） | I40: 組織試験採取、切採法（心筋） | J40: ○ | L40: =IF([1]診療行為!G37=K40, "", "check")
A41: D006-21 | B41: 血液粘弾性検査 | C41: 160217410 | D41: 血液粘弾性検査（一連につき） | E41: - | F41: 6664 | H41: 血液粘弾性検査（一連につき） | I41: 血液粘弾性検査（一連につき） | J41: ○ | L41: =IF([1]診療行為!G38=K41, "", "check")
A42: D222 | B42: 経皮的血液ガス分圧測定、血液ガス連続測定 | C42: 160159450 | D42: 血液ガス連続測定（５時間を超えた場合）（１日につき） | E42: - | F42: 2939 | H42: 血液ガス連続測定（５時間を超えた場合）（１日につき） | I42: 血液ガス連続測定（５時間を超えた場合）（１日につき） | J42: ○ | L42: =IF([1]診療行為!G39=K42, "", "check")
A43: D303 | B43: 胸腔鏡検査 | C43: 160093010 | D43: 胸腔鏡検査 | E43: - | F43: 2070 | H43: 胸腔鏡検査 | I43: 胸腔鏡検査 | J43: ○ | L43: =IF([1]診療行為!G40=K43, "", "check")
A44: D004 | B44: 穿刺液・採取液検査 | C44: 160182110 | D44: マイクロバブルテスト | E44: - | F44: 1105 | H44: マイクロバブルテスト | I44: マイクロバブルテスト | J44: ○ | L44: =IF([1]診療行為!G41=K44, "", "check")
A45: D207 | B45: 体液量等測定 | C45: 160067610 | D45: 循環時間測定 | E45: - | F45: 645 | H45: 循環時間測定 | I45: 循環時間測定 | J45: ○ | L45: =IF([1]診療行為!G42=K45, "", "check")
A46: D314 | B46: 腹腔鏡検査 | C46: 160095010 | D46: 腹腔鏡検査 | E46: - | F46: 492 | H46: 腹腔鏡検査 | I46: 腹腔鏡検査 | J46: ○ | L46: =IF([1]診療行為!G43=K46, "", "check")
...

Sheet 電カル共有項目がNDBに含まれるか
B2: 電カル共有JLACコード | D2: NDB集計有無
B3: 大項目 | C3: 検査項目
B4: 総蛋白(TP) | C4: 総蛋白(TP) | D4: あり
B5: アルブミン | C5: アルブミン | D5: あり
B6: クレアチンキナーゼ(CK) | C6: クレアチンキナーゼ(CK) | D6: あり
B7: AST(GOT) | C7: AST(GOT) | D7: あり
B8: ALT(GPT) | C8: ALT(GPT) | D8: あり
B9: LD(LDH) | C9: LD(LDH) | D9: あり
B10: アルカリホスファターゼ(ALP) | C10: アルカリホスファターゼ(ALP) | D10: あり
B11: γ-GTP(GGT) | C11: γ-GT(γ-GTP) | D11: あり
B12: コリンエステラーゼ(ChE) | C12: コリンエステラーゼ(ChE) | D12: あり
B13: アミラーゼ(AMY) | C13: アミラーゼ(AMY) | D13: あり
B14: クレアチニン(Cre) | C14: 血清クレアチニン(Cre) | D14: あり
B15: シスタチンC(Cys-C) | C15: シスタチンC(Cys-C) | D15: あり
... B92: HIV | C92: HIV-1+2抗原・抗体同時(陽性コントロール比) | D92: あり

Sheet 長谷川さん作業＞

Sheet 作業3_関数削除ランキング
A1: 診療年月：2024年04月～2025年03月 D 検査 外来 ※集計結果が10未満の場合は「‐」で表示（10未満の箇所が1箇所の場合は10以上の最小値を全て「‐」で表示）※集計対象期間内に名称や点数・金額等に変更がある場合、変更後の情報で表示
A2: 診療年月：2024年04月～2025年03月 D 検査 入院 ※集計結果が10未満の場合は「‐」で表示（10未満の箇所が1箇所の場合は10以上の最小値を全て「‐」で表示）※集計対象期間内に名称や点数・金額等に変更がある場合、変更後の情報で表示
A4: 分類コード | B4: 分類名称 | C4: 診療行為コード | D4: 診療行為 | E4: 外来総計（算定回数） | F4: 入院総計（算定回数） | G4: 43+5項目 | H4: 確認用：外来診療行為コード | I4: 確認用：入院診療行為コード | J4: 不一致フラグ
A5: D001 | B5: 尿中特殊物質定性定量検査 | C5: 160003750 | D5: Ｄｅａｎａｎｄ Ｂａｒｎｅｓ反応 | E5: - | F5: - | H5: Ｄｅａｎａｎｄ Ｂａｒｎｅｓ反応 | I5: Ｄｅａｎａｎｄ Ｂａｒｎｅｓ反応 | J5: ○
A6: D001 | B6: 尿中特殊物質定性定量検査 | C6: 160156710 | D6: ポルフィリン症スクリーニングテスト（尿） | E6: - | F6: - | H6: ポルフィリン症スクリーニングテスト（尿） | I6: ポルフィリン症スクリーニングテスト（尿） | J6: ○
A7: D003 | B7: 糞便検査 | C7: 160112610 | D7: ウロビリン（糞便） | E7: - | F7: - | H7: ウロビリン（糞便） | I7: ウロビリン（糞便） | J7: ○
A8: D004-2 | B8: 悪性腫瘍組織検査 | C8: 160221910 | D8: 悪性腫瘍組織検査（処理が容易なもの）（その他のもの）（悪性黒色腫におけるセンチネルリンパ節生検に係る遺伝子検査） | E8: - | F8: - | H8: 悪性腫瘍組織検査（処理が容易なもの）（その他のもの）（悪性黒色腫におけるセンチネルリンパ節生検に係る遺伝子検査） | I8: 悪性腫瘍組織検査（処理が容易なもの）（その他のもの）（悪性黒色腫におけるセンチネルリンパ節生検に係る遺伝子検査） | J8: ○
A9: D005 | B9: 血液形態・機能検査 | C9: 160228250 | D9: ＤＮＡ含有赤血球計数検査 | E9: - | F9: - | H9: ＤＮＡ含有赤血球計数検査 | I9: ＤＮＡ含有赤血球計数検査 | J9: ○
A10: D006 | B10: 出血・凝固検査 | C10: 160012750 | D10: 蛇毒試験 | E10: - | F10: - | H10: 蛇毒試験 | I10: 蛇毒試験 | J10: ○
A11: D006-4 | B11: 遺伝学的検査 | C11: 160239110 | D11: 遺伝学的検査（処理が複雑なもの）（複数疾患） | E11: - | F11: - | H11: 遺伝学的検査（処理が複雑なもの）（複数疾患） | I11: 遺伝学的検査（処理が複雑なもの）（複数疾患） | J11: ○
A12: D006-4 | B12: 遺伝学的検査 | C12: 160239410 | D12: 遺伝学的検査（処理が複雑なもの）（（１）のエに掲げる遺伝子疾患の場合）（複数疾患） | E12: - | F12: - | H12: 遺伝学的検査（処理が複雑なもの）（（１）のエに掲げる遺伝子疾患の場合）（複数疾患） | I12: 遺伝学的検査（処理が複雑なもの）（（１）のエに掲げる遺伝子疾患の場合）（複数疾患） | J12: ○
A13: D006-4 | B13: 遺伝学的検査 | C13: 160239510 | D13: 遺伝学的検査（処理が極めて複雑なもの）（（１）のエに掲げる遺伝子疾患の場合）（複数疾患） | E13: - | F13: - | H13: 遺伝学的検査（処理が極めて複雑なもの）（（１）のエに掲げる遺伝子疾患の場合）（複数疾患） | I13: 遺伝学的検査（処理が極めて複雑なもの）（（１）のエに掲げる遺伝子疾患の場合）（複数疾患） | J13: ○
A14: D006-4 | B14: 遺伝学的検査 | C14: 160239710 | D14: 遺伝学的検査（処理が複雑なもの）（（１）のオに掲げる遺伝子疾患の場合）（複数疾患） | E14: - | F14: - | H14: 遺伝学的検査（処理が複雑なもの）（（１）のオに掲げる遺伝子疾患の場合）（複数疾患） | I14: 遺伝学的検査（処理が複雑なもの）（（１）のオに掲げる遺伝子疾患の場合）（複数疾患） | J14: ○
A15: D006-4 | B15: 遺伝学的検査 | C15: 160239810 | D15: 遺伝学的検査（処理が極めて複雑なもの）（（１）のオに掲げる遺伝子疾患の場合）（複数疾患） | E15: - | F15: - | H15: 遺伝学的検査（処理が極めて複雑なもの）（（１）のオに掲げる遺伝子疾患の場合）（複数疾患） | I15: 遺伝学的検査（処理が極めて複雑なもの）（（１）のオに掲げる遺伝子疾患の場合）（複数疾患） | J15: ○
A16: D006-27 | B16: 悪性腫瘍遺伝子検査（血液・血漿） | C16: 160223750 | D16: 悪性腫瘍遺伝子検査（血液・血漿）（ＭＥＴｅｘ１４遺伝子検査） | E16: - | F16: - | H16: 悪性腫瘍遺伝子検査（血液・血漿）（ＭＥＴｅｘ１４遺伝子検査） | I16: 悪性腫瘍遺伝子検査（血液・血漿）（ＭＥＴｅｘ１４遺伝子検査） | J16: ○
... A36: D417 | B36: 組織試験採取、切採法 | C36: 160100510 | D36: 組織試験採取、切採法（精巣上体（副睾丸）） | E36: - | F36: - | H36: 組織試験採取、切採法（精巣上体（副睾丸）） | I36: 組織試験採取、切採法（精巣上体（副睾丸）） | J36: ○
A37: D226 | B37: 中心静脈圧測定 | C37: 160074410 | D37: 中心静脈圧測定（５回以上の場合）（１日につき） | E37: - | F37: 446039 | H37: 中心静脈圧測定（５回以上の場合）（１日につき） | I37: 中心静脈圧測定（５回以上の場合）（１日につき） | J37: ○
A38: D235-3 | B38: 長期脳波ビデオ同時記録検査 | C38: 160207510 | D38: 長期脳波ビデオ同時記録検査１（１日につき） | E38: - | F38: 15577 | H38: 長期脳波ビデオ同時記録検査１（１日につき） | I38: 長期脳波ビデオ同時記録検査１（１日につき） | J38: ○
A39: D227 | B39: 頭蓋内圧持続測定 | C39: 160103010 | D39: 頭蓋内圧持続測定（３時間を超えた場合）（１日につき） | E39: - | F39: 14584 | H39: 頭蓋内圧持続測定（３時間を超えた場合）（１日につき） | I39: 頭蓋内圧持続測定（３時間を超えた場合）（１日につき） | J39: ○
A40: D417 | B40: 組織試験採取、切採法 | C40: 160188310 | D40: 組織試験採取、切採法（心筋） | E40: - | F40: 12911 | H40: 組織試験採取、切採法（心筋） | I40: 組織試験採取、切採法（心筋） | J40: ○
A41: D006-21 | B41: 血液粘弾性検査 | C41: 160217410 | D41: 血液粘弾性検査（一連につき） | E41: - | F41: 6664 | H41: 血液粘弾性検査（一連につき） | I41: 血液粘弾性検査（一連につき） | J41: ○
A42: D222 | B42: 経皮的血液ガス分圧測定、血液ガス連続測定 | C42: 160159450 | D42: 血液ガス連続測定（５時間を超えた場合）（１日につき） | E42: - | F42: 2939 | H42: 血液ガス連続測定（５時間を超えた場合）（１日につき） | I42: 血液ガス連続測定（５時間を超えた場合）（１日につき） | J42: ○
A43: D303 | B43: 胸腔鏡検査 | C43: 160093010 | D43: 胸腔鏡検査 | E43: - | F43: 2070 | H43: 胸腔鏡検査 | I43: 胸腔鏡検査 | J43: ○
A44: D004 | B44: 穿刺液・採取液検査 | C44: 160182110 | D44: マイクロバブルテスト | E44: - | F44: 1105 | H44: マイクロバブルテスト | I44: マイクロバブルテスト | J44: ○
A45: D207 | B45: 体液量等測定 | C45: 160067610 | D45: 循環時間測定 | E45: - | F45: 645 | H45: 循環時間測定 | I45: 循環時間測定 | J45: ○
A46: D314 | B46: 腹腔鏡検査 | C46: 160095010 | D46: 腹腔鏡検査 | E46: - | F46: 492 | H46: 腹腔鏡検査 | I46: 腹腔鏡検査 | J46: ○
A47: D291-3 | B47: 内服・点滴誘発試験 | C47: 160187410 | D47: 内服・点滴誘発試験 | E47: - | F47: 435 | H47: 内服・点滴誘発試験 | I47: 内服・点滴誘発試験 | J47: ○
A48: D416 | B48: 臓器穿刺、組織採取 | C48: 160098410 | D48: 臓器穿刺、組織採取（開腹によるもの）（腎を含む） | E48: - | F48: 404 | H48: 臓器穿刺、組織採取（開腹によるもの）（腎を含む） | I48: 臓器穿刺、組織採取（開腹によるもの）（腎を含む） | J48: ○
... A77: D012 | B77: 感染症免疫学的検査 | C77: 160042910 | D77: ウイルス抗体価（定性・半定量・定量）（ポリオウイルス２型） | E77: - | F77: 12 | H77: ウイルス抗体価（定性・半定量・定量）（ポリオウイルス２型） | I77: ウイルス抗体価（定性・半定量・定量）（ポリオウイルス２型） | J77: ○
A78: D400 | B78: 血液採取 | C78: 160095710 | D78: 血液採取（静脈） | E78: 182055444 | F78: 84255 | H78: 血液採取（静脈） | I78: 血液採取（静脈） | J78: ○
A79: D026 | B79: 検体検査判断料 | C79: 160061810 | D79: 血液学的検査判断料 | E79: 174761133 | F79: 12480942 | H79: 血液学的検査判断料 | I79: 血液学的検査判断料 | J79: ○
A80: D026 | B80: 検体検査判断料 | C80: 160061910 | D80: 生化学的検査（１）判断料 | E80: 173550281 | F80: 12666526 | H80: 生化学的検査（１）判断料 | I80: 生化学的検査（１）判断料 | J80: ○
A81: D007 | B81: 血液化学検査 | C81: 160019210 | D81: クレアチニン | E81: 154198398 | F81: 44753025 | G81: 〇 | H81: クレアチニン | I81: クレアチニン | J81: ○
A82: D007 | B82: 血液化学検査 | C82: 160022610 | D82: アラニンアミノトランスフェラーゼ（ＡＬＴ） | E82: 153058284 | F82: 43656202 | G82: 〇 | H82: アラニンアミノトランスフェラーゼ（ＡＬＴ） | I82: アラニンアミノトランスフェラーゼ（ＡＬＴ） | J82: ○
A83: D007 | B83: 血液化学検査 | C83: 160022510 | D83: アスパラギン酸アミノトランスフェラーゼ（ＡＳＴ） | E83: 152795361 | F83: 43724121 | G83: 〇 | H83: アスパラギン酸アミノトランスフェラーゼ（ＡＳＴ） | I83: アスパラギン酸アミノトランスフェラーゼ（ＡＳＴ） | J83: ○
A84: D007 | B84: 血液化学検査 | C84: 160019010 | D84: 尿素窒素 | E84: 145836226 | F84: 44657738 | G84: 〇 | H84: 尿素窒素 | I84: 尿素窒素 | J84: ○
A85: D007 | B85: 血液化学検査 | C85: 160020410 | D85: γ－グルタミルトランスフェラーゼ（γ－ＧＴ） | E85: 134267832 | F85: 34323678 | G85: 〇 | H85: γ－グルタミルトランスフェラーゼ（γ－ＧＴ） | I85: γ－グルタミルトランスフェラーゼ（γ－ＧＴ） | J85: ○
A86: D007 | B86: 血液化学検査 | C86: 160019410 | D86: グルコース | E86: 132698638 | F86: 53821138 | G86: 〇 | H86: グルコース | I86: グルコース | J86: ○
A87: D007 | B87: 血液化学検査 | C87: 160021410 | D87: カリウム | E87: 132311576 | F87: 43919120 | G87: 〇 | H87: カリウム | I87: カリウム | J87: ○
A88: D007 | B88: 血液化学検査 | C88: 160021110 | D88: ナトリウム及びクロール | E88: 132102861 | F88: 44636110 | G88: 〇 | H88: ナトリウム及びクロール | I88: ナトリウム及びクロール | J88: ○
...

Sheet 作業2_検査項目のみ抽出
A1: 診療年月：2024年04月～2025年03月 D 検査 外来 ※集計結果が10未満の場合は「‐」で表示（10未満の箇所が1箇所の場合は10以上の最小値を全て「‐」で表示）※集計対象期間内に名称や点数・金額等に変更がある場合、変更後の情報で表示
A2: 診療年月：2024年04月～2025年03月 D 検査 入院 ※集計結果が10未満の場合は「‐」で表示（10未満の箇所が1箇所の場合は10以上の最小値を全て「‐」で表示）※集計対象期間内に名称や点数・金額等に変更がある場合、変更後の情報で表示
A4: 分類コード | B4: 分類名称 | C4: 診療行為コード | D4: 診療行為 | E4: 外来総計（算定回数） | F4: 入院総計（算定回数） | G4: 43+5項目 | H4: 確認用：外来診療行為コード | I4: 確認用：入院診療行為コード | J4: 不一致フラグ
A5: D000 | B5: 尿中一般物質定性半定量検査 | C5: 160000310 | D5: 尿中一般物質定性半定量検査 | E5: 69013004 | F5: =VLOOKUP(C5,入院!$C$5:$F$1463,4,0) -> 10697026 | G5: 〇 | H5: 尿中一般物質定性半定量検査 | I5: =VLOOKUP(C5,入院!$C$5:$F$1463,2,0) -> 尿中一般物質定性半定量検査 | J5: =IF(H5=I5,"○","×") -> ○
A6: D001 | B6: 尿中特殊物質定性定量検査 | C6: 160000410 | D6: 尿蛋白 | E6: 3032343 | F6: =VLOOKUP(C6,入院!$C$5:$F$1463,4,0) -> 1158657 | G6: 〇 | H6: 尿蛋白 | I6: =VLOOKUP(C6,入院!$C$5:$F$1463,2,0) -> 尿蛋白 | J6: =IF(H6=I6,"○","×") -> ○
A7: D001 | B7: 尿中特殊物質定性定量検査 | C7: 160001310 | D7: ＶＭＡ定性（尿） | E7: 1247 | F7: =VLOOKUP(C7,入院!$C$5:$F$1463,4,0) -> 548 | H7: ＶＭＡ定性（尿） | I7: =VLOOKUP(C7,入院!$C$5:$F$1463,2,0) -> ＶＭＡ定性（尿） | J7: =IF(H7=I7,"○","×") -> ○
A8: D001 | B8: 尿中特殊物質定性定量検査 | C8: 160001710 | D8: 尿グルコース | E8: 319114 | F8: =VLOOKUP(C8,入院!$C$5:$F$1463,4,0) -> 158180 | G8: 〇 | H8: 尿グルコース | I8: =VLOOKUP(C8,入院!$C$5:$F$1463,2,0) -> 尿グルコース | J8: =IF(H8=I8,"○","×") -> ○
A9: D001 | B9: 尿中特殊物質定性定量検査 | C9: 160003650 | D9: Ｒｉｍｉｎｇｔｏｎ反応 | E9: 12 | F9: =VLOOKUP(C9,入院!$C$5:$F$1463,4,0) -> - | H9: Ｒｉｍｉｎｇｔｏｎ反応 | I9: =VLOOKUP(C9,入院!$C$5:$F$1463,2,0) -> Ｒｉｍｉｎｇｔｏｎ反応 | J9: =IF(H9=I9,"○","×") -> ○
A10: D001 | B10: 尿中特殊物質定性定量検査 | C10: 160003750 | D10: Ｄｅａｎａｎｄ Ｂａｒｎｅｓ反応 | E10: - | F10: =VLOOKUP(C10,入院!$C$5:$F$1463,4,0) -> - | H10: Ｄｅａｎａｎｄ Ｂａｒｎｅｓ反応 | I10: =VLOOKUP(C10,入院!$C$5:$F$1463,2,0) -> Ｄｅａｎａｎｄ Ｂａｒｎｅｓ反応 | J10: =IF(H10=I10,"○","×") -> ○
A11: D001 | B11: 尿中特殊物質定性定量検査 | C11: 160003910 | D11: 尿浸透圧 | E11: 80419 | F11: =VLOOKUP(C11,入院!$C$5:$F$1463,4,0) -> 403244 | H11: 尿浸透圧 | I11: =VLOOKUP(C11,入院!$C$5:$F$1463,2,0) -> 尿浸透圧 | J11: =IF(H11=I11,"○","×") -> ○
A12: D001 | B12: 尿中特殊物質定性定量検査 | C12: 160004110 | D12: Ｎ－アセチルグルコサミニダーゼ（ＮＡＧ）（尿） | E12: 244672 | F12: =VLOOKUP(C12,入院!$C$5:$F$1463,4,0) -> 237733 | H12: Ｎ－アセチルグルコサミニダーゼ（ＮＡＧ）（尿） | I12: =VLOOKUP(C12,入院!$C$5:$F$1463,2,0) -> Ｎ－アセチルグルコサミニダーゼ（ＮＡＧ）（尿） | J12: =IF(H12=I12,"○","×") -> ○
A13: D001 | B13: 尿中特殊物質定性定量検査 | C13: 160004310 | D13: 黄体形成ホルモン（ＬＨ）定性（尿） | E13: 368651 | F13: =VLOOKUP(C13,入院!$C$5:$F$1463,4,0) -> 107 | H13: 黄体形成ホルモン（ＬＨ）定性（尿） | I13: =VLOOKUP(C13,入院!$C$5:$F$1463,2,0) -> 黄体形成ホルモン（ＬＨ）定性（尿） | J13: =IF(H13=I13,"○","×") -> ○
A14: D001 | B14: 尿中特殊物質定性定量検査 | C14: 160004510 | D14: フィブリン・フィブリノゲン分解産物（ＦＤＰ）（尿） | E14: 4365 | F14: =VLOOKUP(C14,入院!$C$5:$F$1463,4,0) -> 2202 | H14: フィブリン・フィブリノゲン分解産物（ＦＤＰ）（尿） | I14: =VLOOKUP(C14,入院!$C$5:$F$1463,2,0) -> フィブリン・フィブリノゲン分解産物（ＦＤＰ）（尿） | J14: =IF(H14=I14,"○","×") -> ○
A15: D001 | B15: 尿中特殊物質定性定量検査 | C15: 160004610 | D15: δアミノレブリン酸（δ－ＡＬＡ）（尿） | E15: 401 | F15: =VLOOKUP(C15,入院!$C$5:$F$1463,4,0) -> 342 | H15: δアミノレブリン酸（δ－ＡＬＡ）（尿） | I15: =VLOOKUP(C15,入院!$C$5:$F$1463,2,0) -> δアミノレブリン酸（δ－ＡＬＡ）（尿） | J15: =IF(H15=I15,"○","×") -> ○
A16: D001 | B16: 尿中特殊物質定性定量検査 | C16: 160004810 | D16: アルブミン定量（尿） | E16: 3271383 | F16: =VLOOKUP(C16,入院!$C$5:$F$1463,4,0) -> 178884 | H16: アルブミン定量（尿） | I16: =VLOOKUP(C16,入院!$C$5:$F$1463,2,0) -> アルブミン定量（尿） | J16: =IF(H16=I16,"○","×") -> ○
A17: D001 | B17: 尿中特殊物質定性定量検査 | C17: 160111710 | D17: ウロビリノゲン（尿） | E17: 2196 | F17: =VLOOKUP(C17,入院!$C$5:$F$1463,4,0) -> 349 | H17: ウロビリノゲン（尿） | I17: =VLOOKUP(C17,入院!$C$5:$F$1463,2,0) -> ウロビリノゲン（尿） | J17: =IF(H17=I17,"○","×") -> ○
A18: D001 | B18: 尿中特殊物質定性定量検査 | C18: 160111810 | D18: 先天性代謝異常症スクリーニングテスト（尿） | E18: 44 | F18: =VLOOKUP(C18,入院!$C$5:$F$1463,4,0) -> - | H18: 先天性代謝異常症スクリーニングテスト（尿） | I18: =VLOOKUP(C18,入院!$C$5:$F$1463,2,0) -> 先天性代謝異常症スクリーニングテスト（尿） | J18: =IF(H18=I18,"○","×") -> ○
A19: D001 | B19: 尿中特殊物質定性定量検査 | C19: 160112010 | D19: アルブミン定性（尿） | E19: 307675 | F19: =VLOOKUP(C19,入院!$C$5:$F$1463,4,0) -> 13374 | H19: アルブミン定性（尿） | I19: =VLOOKUP(C19,入院!$C$5:$F$1463,2,0) -> アルブミン定性（尿） | J19: =IF(H19=I19,"○","×") -> ○
A20: D001 | B20: 尿中特殊物質定性定量検査 | C20: 160112110 | D20: ポルフォビリノゲン（尿） | E20: 140 | F20: =VLOOKUP(C20,入院!$C$5:$F$1463,4,0) -> 236 | H20: ポルフォビリノゲン（尿） | I20: =VLOOKUP(C20,入院!$C$5:$F$1463,2,0) -> ポルフォビリノゲン（尿） | J20: =IF(H20=I20,"○","×") -> ○
A21: D001 | B21: 尿中特殊物質定性定量検査 | C21: 160112210 | D21: ウロポルフィリン（尿） | E21: 661 | F21: =VLOOKUP(C21,入院!$C$5:$F$1463,4,0) -> 302 | H21: ウロポルフィリン（尿） | I21: =VLOOKUP(C21,入院!$C$5:$F$1463,2,0) -> ウロポルフィリン（尿） | J21: =IF(H21=I21,"○","×") -> ○
A22: D001 | B22: 尿中特殊物質定性定量検査 | C22: 160112310 | D22: コプロポルフィリン（尿） | E22: 363 | F22: =VLOOKUP(C22,入院!$C$5:$F$1463,4,0) -> 183 | H22: コプロポルフィリン（尿） | I22: =VLOOKUP(C22,入院!$C$5:$F$1463,2,0) -> コプロポルフィリン（尿） | J22: =IF(H22=I22,"○","×") -> ○
A23: D001 | B23: 尿中特殊物質定性定量検査 | C23: 160134350 | D23: ポリアミン（尿） | E23: - | F23: =VLOOKUP(C23,入院!$C$5:$F$1463,4,0) -> 12 | H23: ポリアミン（尿） | I23: =VLOOKUP(C23,入院!$C$5:$F$1463,2,0) -> ポリアミン（尿） | J23: =IF(H23=I23,"○","×") -> ○
A24: D001 | B24: 尿中特殊物質定性定量検査 | C24: 160156710 | D24: ポルフィリン症スクリーニングテスト（尿） | E24: - | F24: =VLOOKUP(C24,入院!$C$5:$F$1463,4,0) -> - | H24: ポルフィリン症スクリーニングテスト（尿） | I24: =VLOOKUP(C24,入院!$C$5:$F$1463,2,0) -> ポルフィリン症スクリーニングテスト（尿） | J24: =IF(H24=I24,"○","×") -> ○
A25: D001 | B25: 尿中特殊物質定性定量検査 | C25: 160157750 | D25: トランスフェリン（尿） | E25: 5099 | F25: =VLOOKUP(C25,入院!$C$5:$F$1463,4,0) -> 9030 | H25: トランスフェリン（尿） | I25: =VLOOKUP(C25,入院!$C$5:$F$1463,2,0) -> トランスフェリン（尿） | J25: =IF(H25=I25,"○","×") -> ○
A26: D001 | B26: 尿中特殊物質定性定量検査 | C26: 160169250 | D26: ４型コラーゲン（尿） | E26: 2516 | F26: =VLOOKUP(C26,入院!$C$5:$F$1463,4,0) -> 385 | H26: ４型コラーゲン（尿） | I26: =VLOOKUP(C26,入院!$C$5:$F$1463,2,0) -> ４型コラーゲン（尿） | J26: =IF(H26=I26,"○","×") -> ○
A27: D001 | B27: 尿中特殊物質定性定量検査 | C27: 160176350 | D27: クレアチニン試験紙法（尿）（蛋白／クレアチニン比） | E27: 315581 | F27: =VLOOKUP(C27,入院!$C$5:$F$1463,4,0) -> 82372 | G27: 〇 | H27: クレアチニン試験紙法（尿）（蛋白／クレアチニン比） | I27: =VLOOKUP(C27,入院!$C$5:$F$1463,2,0) -> クレアチニン試験紙法（尿）（蛋白／クレアチニン比） | J27: =IF(H27=I27,"○","×") -> ○
A28: D001 | B28: 尿中特殊物質定性定量検査 | C28: 160189250 | D28: Ｌ型脂肪酸結合蛋白（Ｌ－ＦＡＢＰ）（尿） | E28: 88871 | F28: =VLOOKUP(C28,入院!$C$5:$F$1463,4,0) -> 22267 | H28: Ｌ型脂肪酸結合蛋白（Ｌ－ＦＡＢＰ）（尿） | I28: =VLOOKUP(C28,入院!$C$5:$F$1463,2,0) -> Ｌ型脂肪酸結合蛋白（Ｌ－ＦＡＢＰ）（尿） | J28: =IF(H28=I28,"○","×") -> ○
A29: D001 | B29: 尿中特殊物質定性定量検査 | C29: 160189950 | D29: 総ヨウ素（尿） | E29: 256 | F29: =VLOOKUP(C29,入院!$C$5:$F$1463,4,0) -> 320 | H29: 総ヨウ素（尿） | I29: =VLOOKUP(C29,入院!$C$5:$F$1463,2,0) -> 総ヨウ素（尿） | J29: =IF(H29=I29,"○","×") -> ○
A30: D001 | B30: 尿中特殊物質定性定量検査 | C30: 160209650 | D30: 好中球ゼラチナーゼ結合性リポカリン（ＮＧＡＬ）（尿） | E30: 1879 | F30: =VLOOKUP(C30,入院!$C$5:$F$1463,4,0) -> 30238 | H30: 好中球ゼラチナーゼ結合性リポカリン（ＮＧＡＬ）（尿） | I30: =VLOOKUP(C30,入院!$C$5:$F$1463,2,0) -> 好中球ゼラチナーゼ結合性リポカリン（ＮＧＡＬ）（尿） | J30: =IF(H30=I30,"○","×") -> ○
A31: D001 | B31: 尿中特殊物質定性定量検査 | C31: 160210610 | D31: シュウ酸（尿） | E31: 130 | F31: =VLOOKUP(C31,入院!$C$5:$F$1463,4,0) -> 264 | H31: シュウ酸（尿） | I31: =VLOOKUP(C31,入院!$C$5:$F$1463,2,0) -> シュウ酸（尿） | J31: =IF(H31=I31,"○","×") -> ○
A32: D001 | B32: 尿中特殊物質定性定量検査 | C32: 160224650 | D32: トリプシノーゲン２（尿） | E32: 1216 | F32: =VLOOKUP(C32,入院!$C$5:$F$1463,4,0) -> 2852 | H32: トリプシノーゲン２（尿） | I32: =VLOOKUP(C32,入院!$C$5:$F$1463,2,0) -> トリプシノーゲン２（尿） | J32: =IF(H32=I32,"○","×") -> ○
A33: D001 | B33: 尿中特殊物質定性定量検査 | C33: 160237350 | D33: プロスタグランジンＥ主要代謝物（尿） | E33: 956 | F33: =VLOOKUP(C33,入院!$C$5:$F$1463,4,0) -> 304 | H33: プロスタグランジンＥ主要代謝物（尿） | I33: =VLOOKUP(C33,入院!$C$5:$F$1463,2,0) -> プロスタグランジンＥ主要代謝物（尿） | J33: =IF(H33=I33,"○","×") -> ○
A34: D002 | B34: 尿沈渣（鏡検法） | C34: 160005010 | D34: 尿沈渣（鏡検法） | E34: 18290110 | F34: =VLOOKUP(C34,入院!$C$5:$F$1463,4,0) -> 4369238 | H34: 尿沈渣（鏡検法） | I34: =VLOOKUP(C34,入院!$C$5:$F$1463,2,0) -> 尿沈渣（鏡検法） | J34: =IF(H34=I34,"○","×") -> ○
A35: D002-2 | B35: 尿沈渣（フローサイトメトリー法） | C35: 160159550 | D35: 尿沈渣（フローサイトメトリー法） | E35: 3669858 | F35: =VLOOKUP(C35,入院!$C$5:$F$1463,4,0) -> 2126755 | H35: 尿沈渣（フローサイトメトリー法） | I35: =VLOOKUP(C35,入院!$C$5:$F$1463,2,0) -> 尿沈渣（フローサイトメトリー法） | J35: =IF(H35=I35,"○","×") -> ○
A36: D003 | B36: 糞便検査 | C36: 160005510 | D36: 糞便塗抹顕微鏡検査（虫卵、脂肪及び消化状況観察を含む。） | E36: 7848 | F36: =VLOOKUP(C36,入院!$C$5:$F$1463,4,0) -> 8548 | H36: 糞便塗抹顕微鏡検査（虫卵、脂肪及び消化状況観察を含む。） | I36: =VLOOKUP(C36,入院!$C$5:$F$1463,2,0) -> 糞便塗抹顕微鏡検査（虫卵、脂肪及び消化状況観察を含む。） | J36: =IF(H36=I36,"○","×") -> ○
A37: D003 | B37: 糞便検査 | C37: 160005710 | D37: 虫卵検出（集卵法）（糞便） | E37: 2917 | F37: =VLOOKUP(C37,入院!$C$5:$F$1463,4,0) -> 3138 | H37: 虫卵検出（集卵法）（糞便） | I37: =VLOOKUP(C37,入院!$C$5:$F$1463,2,0) -> 虫卵検出（集卵法）（糞便） | J37: =IF(H37=I37,"○","×") -> ○
A38: D003 | B38: 糞便検査 | C38: 160006310 | D38: 糞便中脂質 | E38: 78 | F38: =VLOOKUP(C38,入院!$C$5:$F$1463,4,0) -> 125 | H38: 糞便中脂質 | I38: =VLOOKUP(C38,入院!$C$5:$F$1463,2,0) -> 糞便中脂質 | J38: =IF(H38=I38,"○","×") -> ○
A39: D003 | B39: 糞便検査 | C39: 160006410 | D39: 虫体検出（糞便） | E39: 1494 | F39: =VLOOKUP(C39,入院!$C$5:$F$1463,4,0) -> 1156 | H39: 虫体検出（糞便） | I39: =VLOOKUP(C39,入院!$C$5:$F$1463,2,0) -> 虫体検出（糞便） | J39: =IF(H39=I39,"○","×") -> ○
... A42: D003 | B42: 糞便検査 | C42: 160006810 | D42: 糞便中ヘモグロビン | E42: 429405 | F42: =VLOOKUP(C42,入院!$C$5:$F$1463,4,0) -> 181428 | H42: 糞便中ヘモグロビン | I42: =VLOOKUP(C42,入院!$C$5:$F$1463,2,0) -> 糞便中ヘモグロビン | J42: =IF(H42=I42,"○","×") -> ○
A43: D003 | B43: 糞便検査 | C43: 160112610 | D43: ウロビリン（糞便） | E43: - | F43: =VLOOKUP(C43,入院!$C$5:$F$1463,4,0) -> - | H43: ウロビリン（糞便） | I43: =VLOOKUP(C43,入院!$C$5:$F$1463,2,0) -> ウロビリン（糞便） | J43: =IF(H43=I43,"○","×") -> ○
...

Sheet 作業1_外来入院データ1枚に統合_両シート共通項目のみ抽出
A1: 診療年月：2024年04月～2025年03月 D 検査 外来 ※集計結果が10未満の場合は「‐」で表示（10未満の箇所が1箇所の場合は10以上の最小値を全て「‐」で表示）※集計対象期間内に名称や点数・金額等に変更がある場合、変更後の情報で表示
A2: 診療年月：2024年04月～2025年03月 D 検査 入院 ※集計結果が10未満の場合は「‐」で表示（10未満の箇所が1箇所の場合は10以上の最小値を全て「‐」で表示）※集計対象期間内に名称や点数・金額等に変更がある場合、変更後の情報で表示
A4: 分類コード | B4: 分類名称 | C4: 診療行為コード | D4: 診療行為 | E4: 外来総計（算定回数） | F4: 入院総計（算定回数） | G4: 確認用：外来診療行為コード | H4: 確認用：入院診療行為コード | I4: 不一致フラグ
A5: D000 | B5: 尿中一般物質定性半定量検査 | C5: 160000310 | D5: 尿中一般物質定性半定量検査 | E5: 69013004 | F5: =VLOOKUP(C5,入院!$C$5:$F$1463,4,0) -> 10697026 | G5: 尿中一般物質定性半定量検査 | H5: =VLOOKUP(C5,入院!$C$5:$F$1463,2,0) -> 尿中一般物質定性半定量検査 | I5: =IF(G5=H5,"○","×") -> ○
A6: D001 | B6: 尿中特殊物質定性定量検査 | C6: 160000410 | D6: 尿蛋白 | E6: 3032343 | F6: =VLOOKUP(C6,入院!$C$5:$F$1463,4,0) -> 1158657 | G6: 尿蛋白 | H6: =VLOOKUP(C6,入院!$C$5:$F$1463,2,0) -> 尿蛋白 | I6: =IF(G6=H6,"○","×") -> ○
A7: D001 | B7: 尿中特殊物質定性定量検査 | C7: 160001310 | D7: ＶＭＡ定性（尿） | E7: 1247 | F7: =VLOOKUP(C7,入院!$C$5:$F$1463,4,0) -> 548 | G7: ＶＭＡ定性（尿） | H7: =VLOOKUP(C7,入院!$C$5:$F$1463,2,0) -> ＶＭＡ定性（尿） | I7: =IF(G7=H7,"○","×") -> ○
A8: D001 | B8: 尿中特殊物質定性定量検査 | C8: 160001710 | D8: 尿グルコース | E8: 319114 | F8: =VLOOKUP(C8,入院!$C$5:$F$1463,4,0) -> 158180 | G8: 尿グルコース | H8: =VLOOKUP(C8,入院!$C$5:$F$1463,2,0) -> 尿グルコース | I8: =IF(G8=H8,"○","×") -> ○
A9: D001 | B9: 尿中特殊物質定性定量検査 | C9: 160003650 | D9: Ｒｉｍｉｎｇｔｏｎ反応 | E9: 12 | F9: =VLOOKUP(C9,入院!$C$5:$F$1463,4,0) -> - | G9: Ｒｉｍｉｎｇｔｏｎ反応 | H9: =VLOOKUP(C9,入院!$C$5:$F$1463,2,0) -> Ｒｉｍｉｎｇｔｏｎ反応 | I9: =IF(G9=H9,"○","×") -> ○
A10: D001 | B10: 尿中特殊物質定性定量検査 | C10: 160003750 | D10: Ｄｅａｎａｎｄ Ｂａｒｎｅｓ反応 | E10: - | F10: =VLOOKUP(C10,入院!$C$5:$F$1463,4,0) -> - | G10: Ｄｅａｎａｎｄ Ｂａｒｎｅｓ反応 | H10: =VLOOKUP(C10,入院!$C$5:$F$1463,2,0) -> Ｄｅａｎａｎｄ Ｂａｒｎｅｓ反応 | I10: =IF(G10=H10,"○","×") -> ○
A11: D001 | B11: 尿中特殊物質定性定量検査 | C11: 160003910 | D11: 尿浸透圧 | E11: 80419 | F11: =VLOOKUP(C11,入院!$C$5:$F$1463,4,0) -> 403244 | G11: 尿浸透圧 | H11: =VLOOKUP(C11,入院!$C$5:$F$1463,2,0) -> 尿浸透圧 | I11: =IF(G11=H11,"○","×") -> ○
A12: D001 | B12: 尿中特殊物質定性定量検査 | C12: 160004110 | D12: Ｎ－アセチルグルコサミニダーゼ（ＮＡＧ）（尿） | E12: 244672 | F12: =VLOOKUP(C12,入院!$C$5:$F$1463,4,0) -> 237733 | G12: Ｎ－アセチルグルコサミニダーゼ（ＮＡＧ）（尿） | H12: =VLOOKUP(C12,入院!$C$5:$F$1463,2,0) -> Ｎ－アセチルグルコサミニダーゼ（ＮＡＧ）（尿） | I12: =IF(G12=H12,"○","×") -> ○
A13: D001 | B13: 尿中特殊物質定性定量検査 | C13: 160004310 | D13: 黄体形成ホルモン（ＬＨ）定性（尿） | E13: 368651 | F13: =VLOOKUP(C13,入院!$C$5:$F$1463,4,0) -> 107 | G13: 黄体形成ホルモン（ＬＨ）定性（尿） | H13: =VLOOKUP(C13,入院!$C$5:$F$1463,2,0) -> 黄体形成ホルモン（ＬＨ）定性（尿） | I13: =IF(G13=H13,"○","×") -> ○
A14: D001 | B14: 尿中特殊物質定性定量検査 | C14: 160004510 | D14: フィブリン・フィブリノゲン分解産物（ＦＤＰ）（尿） | E14: 4365 | F14: =VLOOKUP(C14,入院!$C$5:$F$1463,4,0) -> 2202 | G14: フィブリン・フィブリノゲン分解産物（ＦＤＰ）（尿） | H14: =VLOOKUP(C14,入院!$C$5:$F$1463,2,0) -> フィブリン・フィブリノゲン分解産物（ＦＤＰ）（尿） | I14: =IF(G14=H14,"○","×") -> ○
A15: D001 | B15: 尿中特殊物質定性定量検査 | C15: 160004610 | D15: δアミノレブリン酸（δ－ＡＬＡ）（尿） | E15: 401 | F15: =VLOOKUP(C15,入院!$C$5:$F$1463,4,0) -> 342 | G15: δアミノレブリン酸（δ－ＡＬＡ）（尿） | H15: =VLOOKUP(C15,入院!$C$5:$F$1463,2,0) -> δアミノレブリン酸（δ－ＡＬＡ）（尿） | I15: =IF(G15=H15,"○","×") -> ○
A16: D001 | B16: 尿中特殊物質定性定量検査 | C16: 160004810 | D16: アルブミン定量（尿） | E16: 3271383 | F16: =VLOOKUP(C16,入院!$C$5:$F$1463,4,0) -> 178884 | G16: アルブミン定量（尿） | H16: =VLOOKUP(C16,入院!$C$5:$F$1463,2,0) -> アルブミン定量（尿） | I16: =IF(G16=H16,"○","×") -> ○
A17: D001 | B17: 尿中特殊物質定性定量検査 | C17: 160111710 | D17: ウロビリノゲン（尿） | E17: 2196 | F17: =VLOOKUP(C17,入院!$C$5:$F$1463,4,0) -> 349 | G17: ウロビリノゲン（尿） | H17: =VLOOKUP(C17,入院!$C$5:$F$1463,2,0) -> ウロビリノゲン（尿） | I17: =IF(G17=H17,"○","×") -> ○
A18: D001 | B18: 尿中特殊物質定性定量検査 | C18: 160111810 | D18: 先天性代謝異常症スクリーニングテスト（尿） | E18: 44 | F18: =VLOOKUP(C18,入院!$C$5:$F$1463,4,0) -> - | G18: 先天性代謝異常症スクリーニングテスト（尿） | H18: =VLOOKUP(C18,入院!$C$5:$F$1463,2,0) -> 先天性代謝異常症スクリーニングテスト（尿） | I18: =IF(G18=H18,"○","×") -> ○
A19: D001 | B19: 尿中特殊物質定性定量検査 | C19: 160112010 | D19: アルブミン定性（尿） | E19: 307675 | F19: =VLOOKUP(C19,入院!$C$5:$F$1463,4,0) -> 13374 | G19: アルブミン定性（尿） | H19: =VLOOKUP(C19,入院!$C$5:$F$1463,2,0) -> アルブミン定性（尿） | I19: =IF(G19=H19,"○","×") -> ○
A20: D001 | B20: 尿中特殊物質定性定量検査 | C20: 160112110 | D20: ポルフォビリノゲン（尿） | E20: 140 | F20: =VLOOKUP(C20,入院!$C$5:$F$1463,4,0) -> 236 | G20: ポルフォビリノゲン（尿） | H20: =VLOOKUP(C20,入院!$C$5:$F$1463,2,0) -> ポルフォビリノゲン（尿） | I20: =IF(G20=H20,"○","×") -> ○
A21: D001 | B21: 尿中特殊物質定性定量検査 | C21: 160112210 | D21: ウロポルフィリン（尿） | E21: 661 | F21: =VLOOKUP(C21,入院!$C$5:$F$1463,4,0) -> 302 | G21: ウロポルフィリン（尿） | H21: =VLOOKUP(C21,入院!$C$5:$F$1463,2,0) -> ウロポルフィリン（尿） | I21: =IF(G21=H21,"○","×") -> ○
A22: D001 | B22: 尿中特殊物質定性定量検査 | C22: 160112310 | D22: コプロポルフィリン（尿） | E22: 363 | F22: =VLOOKUP(C22,入院!$C$5:$F$1463,4,0) -> 183 | G22: コプロポルフィリン（尿） | H22: =VLOOKUP(C22,入院!$C$5:$F$1463,2,0) -> コプロポルフィリン（尿） | I22: =IF(G22=H22,"○","×") -> ○
A23: D001 | B23: 尿中特殊物質定性定量検査 | C23: 160134350 | D23: ポリアミン（尿） | E23: - | F23: =VLOOKUP(C23,入院!$C$5:$F$1463,4,0) -> 12 | G23: ポリアミン（尿） | H23: =VLOOKUP(C23,入院!$C$5:$F$1463,2,0) -> ポリアミン（尿） | I23: =IF(G23=H23,"○","×") -> ○
A24: D001 | B24: 尿中特殊物質定性定量検査 | C24: 160156710 | D24: ポルフィリン症スクリーニングテスト（尿） | E24: - | F24: =VLOOKUP(C24,入院!$C$5:$F$1463,4,0) -> - | G24: ポルフィリン症スクリーニングテスト（尿） | H24: =VLOOKUP(C24,入院!$C$5:$F$1463,2,0) -> ポルフィリン症スクリーニングテスト（尿） | I24: =IF(G24=H24,"○","×") -> ○
A25: D001 | B25: 尿中特殊物質定性定量検査 | C25: 160157750 | D25: トランスフェリン（尿） | E25: 5099 | F25: =VLOOKUP(C25,入院!$C$5:$F$1463,4,0) -> 9030 | G25: トランスフェリン（尿） | H25: =VLOOKUP(C25,入院!$C$5:$F$1463,2,0) -> トランスフェリン（尿） | I25: =IF(G25=H25,"○","×") -> ○
A26: D001 | B26: 尿中特殊物質定性定量検査 | C26: 160169250 | D26: ４型コラーゲン（尿） | E26: 2516 | F26: =VLOOKUP(C26,入院!$C$5:$F$1463,4,0) -> 385 | G26: ４型コラーゲン（尿） | H26: =VLOOKUP(C26,入院!$C$5:$F$1463,2,0) -> ４型コラーゲン（尿） | I26: =IF(G26=H26,"○","×") -> ○
A27: D001 | B27: 尿中特殊物質定性定量検査 | C27: 160176350 | D27: クレアチニン試験紙法（尿）（蛋白／クレアチニン比） | E27: 315581 | F27: =VLOOKUP(C27,入院!$C$5:$F$1463,4,0) -> 82372 | G27: クレアチニン試験紙法（尿）（蛋白／クレアチニン比） | H27: =VLOOKUP(C27,入院!$C$5:$F$1463,2,0) -> クレアチニン試験紙法（尿）（蛋白／クレアチニン比） | I27: =IF(G27=H27,"○","×") -> ○
A28: D001 | B28: 尿中特殊物質定性定量検査 | C28: 160189250 | D28: Ｌ型脂肪酸結合蛋白（Ｌ－ＦＡＢＰ）（尿） | E28: 88871 | F28: =VLOOKUP(C28,入院!$C$5:$F$1463,4,0) -> 22267 | G28: Ｌ型脂肪酸結合蛋白（Ｌ－ＦＡＢＰ）（尿） | H28: =VLOOKUP(C28,入院!$C$5:$F$1463,2,0) -> Ｌ型脂肪酸結合蛋白（Ｌ－ＦＡＢＰ）（尿） | I28: =IF(G28=H28,"○","×") -> ○
A29: D001 | B29: 尿中特殊物質定性定量検査 | C29: 160189950 | D29: 総ヨウ素（尿） | E29: 256 | F29: =VLOOKUP(C29,入院!$C$5:$F$1463,4,0) -> 320 | G29: 総ヨウ素（尿） | H29: =VLOOKUP(C29,入院!$C$5:$F$1463,2,0) -> 総ヨウ素（尿） | I29: =IF(G29=H29,"○","×") -> ○
A30: D001 | B30: 尿中特殊物質定性定量検査 | C30: 160209650 | D30: 好中球ゼラチナーゼ結合性リポカリン（ＮＧＡＬ）（尿） | E30: 1879 | F30: =VLOOKUP(C30,入院!$C$5:$F$1463,4,0) -> 30238 | G30: 好中球ゼラチナーゼ結合性リポカリン（ＮＧＡＬ）（尿） | H30: =VLOOKUP(C30,入院!$C$5:$F$1463,2,0) -> 好中球ゼラチナーゼ結合性リポカリン（ＮＧＡＬ）（尿） | I30: =IF(G30=H30,"○","×") -> ○
A31: D001 | B31: 尿中特殊物質定性定量検査 | C31: 160210610 | D31: シュウ酸（尿） | E31: 130 | F31: =VLOOKUP(C31,入院!$C$5:$F$1463,4,0) -> 264 | G31: シュウ酸（尿） | H31: =VLOOKUP(C31,入院!$C$5:$F$1463,2,0) -> シュウ酸（尿） | I31: =IF(G31=H31,"○","×") -> ○
A32: D001 | B32: 尿中特殊物質定性定量検査 | C32: 160224650 | D32: トリプシノーゲン２（尿） | E32: 1216 | F32: =VLOOKUP(C32,入院!$C$5:$F$1463,4,0) -> 2852 | G32: トリプシノーゲン２（尿） | H32: =VLOOKUP(C32,入院!$C$5:$F$1463,2,0) -> トリプシノーゲン２（尿） | I32: =IF(G32=H32,"○","×") -> ○
A33: D001 | B33: 尿中特殊物質定性定量検査 | C33: 160237350 | D33: プロスタグランジンＥ主要代謝物（尿） | E33: 956 | F33: =VLOOKUP(C33,入院!$C$5:$F$1463,4,0) -> 304 | G33: プロスタグランジンＥ主要代謝物（尿） | H33: =VLOOKUP(C33,入院!$C$5:$F$1463,2,0) -> プロスタグランジンＥ主要代謝物（尿） | I33: =IF(G33=H33,"○","×") -> ○
A34: D002 | B34: 尿沈渣（鏡検法） | C34: 160005010 | D34: 尿沈渣（鏡検法） | E34: 18290110 | F34: =VLOOKUP(C34,入院!$C$5:$F$1463,4,0) -> 4369238 | G34: 尿沈渣（鏡検法） | H34: =VLOOKUP(C34,入院!$C$5:$F$1463,2,0) -> 尿沈渣（鏡検法） | I34: =IF(G34=H34,"○","×") -> ○
A35: D002-2 | B35: 尿沈渣（フローサイトメトリー法） | C35: 160159550 | D35: 尿沈渣（フローサイトメトリー法） | E35: 3669858 | F35: =VLOOKUP(C35,入院!$C$5:$F$1463,4,0) -> 2126755 | G35: 尿沈渣（フローサイトメトリー法） | H35: =VLOOKUP(C35,入院!$C$5:$F$1463,2,0) -> 尿沈渣（フローサイトメトリー法） | I35: =IF(G35=H35,"○","×") -> ○
A36: D003 | B36: 糞便検査 | C36: 160005510 | D36: 糞便塗抹顕微鏡検査（虫卵、脂肪及び消化状況観察を含む。） | E36: 7848 | F36: =VLOOKUP(C36,入院!$C$5:$F$1463,4,0) -> 8548 | G36: 糞便塗抹顕微鏡検査（虫卵、脂肪及び消化状況観察を含む。） | H36: =VLOOKUP(C36,入院!$C$5:$F$1463,2,0) -> 糞便塗抹顕微鏡検査（虫卵、脂肪及び消化状況観察を含む。） | I36: =IF(G36=H36,"○","×") -> ○
... A42: D003 | B42: 糞便検査 | C42: 160006810 | D42: 糞便中ヘモグロビン | E42: 429405 | F42: =VLOOKUP(C42,入院!$C$5:$F$1463,4,0) -> 181428 | G42: 糞便中ヘモグロビン | H42: =VLOOKUP(C42,入院!$C$5:$F$1463,2,0) -> 糞便中ヘモグロビン | I42: =IF(G42=H42,"○","×") -> ○
A43: D003 | B43: 糞便検査 | C43: 160112610 | D43: ウロビリン（糞便） | E43: - | F43: =VLOOKUP(C43,入院!$C$5:$F$1463,4,0) -> - | G43: ウロビリン（糞便） | H43: =VLOOKUP(C43,入院!$C$5:$F$1463,2,0) -> ウロビリン（糞便） | I43: =IF(G43=H43,"○","×") -> ○
A44: D003 | B44: 糞便検査 | C44: 160113110 | D44: 糞便中ヘモグロビン及びトランスフェリン定性・定量 | E44: 112030 | F44: =VLOOKUP(C44,入院!$C$5:$F$1463,4,0) -> 67441 | G44: 糞便中ヘモグロビン及びトランスフェリン定性・定量 | H44: =VLOOKUP(C44,入院!$C$5:$F$1463,2,0) -> 糞便中ヘモグロビン及びトランスフェリン定性・定量 | I44: =IF(G44=H44,"○","×") -> ○
A45: D003 | B45: 糞便検査 | C45: 160210050 | D45: カルプロテクチン（糞便） | E45: 72831 | F45: =VLOOKUP(C45,入院!$C$5:$F$1463,4,0) -> 5247 | G45: カルプロテクチン（糞便） | H45: =VLOOKUP(C45,入院!$C$5:$F$1463,2,0) -> カルプロテクチン（糞便） | I45: =IF(G45=H45,"○","×") -> ○
A46: D004 | B46: 穿刺液・採取液検査 | C46: 160058050 | D46: ヒューナー検査 | E46: 51789 | F46: =VLOOKUP(C46,入院!$C$5:$F$1463,4,0) -> - | G46: ヒューナー検査 | H46: =VLOOKUP(C46,入院!$C$5:$F$1463,2,0) -> ヒューナー検査 | I46: =IF(G46=H46,"○","×") -> ○
...

Sheet 外来
A1: 診療年月：2024年04月～2025年03月 D 検査 外来 ※集計結果が10未満の場合は「‐」で表示（10未満の箇所が1箇所の場合は10以上の最小値を全て「‐」で表示）※集計対象期間内に名称や点数・金額等に変更がある場合、変更後の情報で表示
A3: 分類 コード | B3: 分類名称 | C3: 診療行為 コード | D3: 診療行為 | E3: 点数 | F3: 総計 (算定回数) | G3: 4月 | H3: 5月 | I3: 6月 | J3: 7月 | K3: 8月 | L3: 9月 | M3: 10月 | N3: 11月 | O3: 12月 | P3: 1月 | Q3: 2月 | R3: 3月
A5: D000 | B5: 尿中一般物質定性半定量検査 | C5: 160000310 | D5: 尿中一般物質定性半定量検査 | E5: 26 | F5: 69013004 | G5: 6078970 | H5: 5883542 | I5: 5759955 | J5: 5981129 | K5: 5561140 | L5: 5613624 | M5: 5990603 | N5: 5638445 | O5: 5734836 | P5: 5553441 | Q5: 5339619 | R5: 5877700
A6: D001 | B6: 尿中特殊物質定性定量検査 | C6: 160000410 | D6: 尿蛋白 | E6: 7 | F6: 3032343 | G6: 256381 | H6: 247698 | I6: 251084 | J6: 265035 | K6: 244527 | L6: 248771 | M6: 265490 | N6: 247491 | O6: 252470 | P6: 246795 | Q6: 239879 | R6: 266722
A7: D001 | B7: 尿中特殊物質定性定量検査 | C7: 160001310 | D7: ＶＭＡ定性（尿） | E7: 9 | F7: 1247 | G7: 119 | H7: 120 | I7: 94 | J7: 74 | K7: 69 | L7: 95 | M7: 117 | N7: 133 | O7: 103 | P7: 110 | Q7: 117 | R7: 96
A8: D001 | B8: 尿中特殊物質定性定量検査 | C8: 160001710 | D8: 尿グルコース | E8: 9 | F8: 319114 | G8: 35631 | H8: 33454 | I8: 32334 | J8: 33199 | K8: 27839 | L8: 26569 | M8: 26108 | N8: 23591 | O8: 22237 | P8: 19833 | Q8: 18736 | R8: 19583
A9: D001 | B9: 尿中特殊物質定性定量検査 | C9: 160003650 | D9: Ｒｉｍｉｎｇｔｏｎ反応 | E9: 17 | F9: 12 | G9: - | H9: - | I9: 0 | J9: - | K9: - | L9: - | M9: - | N9: - | O9: - | P9: - | Q9: - | R9: -
A10: D001 | B10: 尿中特殊物質定性定量検査 | C10: 160003750 | D10: Ｄｅａｎａｎｄ Ｂａｒｎｅｓ反応 | E10: 17 | F10: - | G10: - | H10: - | I10: - | J10: - | K10: - | L10: - | M10: - | N10: - | O10: - | P10: - | Q10: - | R10: -
A11: D001 | B11: 尿中特殊物質定性定量検査 | C11: 160003910 | D11: 尿浸透圧 | E11: 16 | F11: 80419 | G11: 6890 | H11: 6655 | I11: 7366 | J11: 7791 | K11: 7399 | L11: 6636 | M11: 6733 | N11: 6385 | O11: 6162 | P11: 5905 | Q11: 5846 | R11: 6651
A12: D001 | B12: 尿中特殊物質定性定量検査 | C12: 160004110 | D12: Ｎ－アセチルグルコサミニダーゼ（ＮＡＧ）（尿） | E12: 41 | F12: 244672 | G12: 21302 | H12: 19541 | I12: 20433 | J12: 22665 | K12: 20643 | L12: 20677 | M12: 21735 | N12: 20236 | O12: 20046 | P12: 18958 | Q12: 18172 | R12: 20264
A13: D001 | B13: 尿中特殊物質定性定量検査 | C13: 160004310 | D13: 黄体形成ホルモン（ＬＨ）定性（尿） | E13: 72 | F13: 368651 | G13: 31654 | H13: 29906 | I13: 30928 | J13: 32598 | K13: 29316 | L13: 30417 | M13: 33176 | N13: 31626 | O13: 29210 | P13: 28520 | Q13: 28901 | R13: 32399
A14: D001 | B14: 尿中特殊物質定性定量検査 | C14: 160004510 | D14: フィブリン・フィブリノゲン分解産物（ＦＤＰ）（尿） | E14: 72 | F14: 4365 | G14: 379 | H14: 347 | I14: 366 | J14: 428 | K14: 444 | L14: 408 | M14: 357 | N14: 332 | O14: 338 | P14: 315 | Q14: 295 | R14: 356
A15: D001 | B15: 尿中特殊物質定性定量検査 | C15: 160004610 | D15: δアミノレブリン酸（δ－ＡＬＡ）（尿） | E15: 106 | F15: 401 | G15: 35 | H15: 41 | I15: 33 | J15: 31 | K15: 29 | L15: 24 | M15: 29 | N15: 27 | O15: 29 | P15: 49 | Q15: 35 | R15: 39
A16: D001 | B16: 尿中特殊物質定性定量検査 | C16: 160004810 | D16: アルブミン定量（尿） | E16: 99 | F16: 3271383 | G16: 291436 | H16: 271823 | I16: 271490 | J16: 277211 | K16: 251105 | L16: 260602 | M16: 282879 | N16: 260076 | O16: 270908 | P16: 272439 | Q16: 265097 | R16: 296317
A17: D001 | B17: 尿中特殊物質定性定量検査 | C17: 160111710 | D17: ウロビリノゲン（尿） | E17: 16 | F17: 2196 | G17: 126 | H17: 146 | I17: 166 | J17: 222 | K17: 212 | L17: 217 | M17: 232 | N17: 166 | O17: 175 | P17: 172 | Q17: 155 | R17: 207
A18: D001 | B18: 尿中特殊物質定性定量検査 | C18: 160111810 | D18: 先天性代謝異常症スクリーニングテスト（尿） | E18: 16 | F18: 44 | G18: 0 | H18: - | I18: - | J18: - | K18: - | L18: - | M18: - | N18: 10 | O18: - | P18: - | Q18: - | R18: -
A19: D001 | B19: 尿中特殊物質定性定量検査 | C19: 160112010 | D19: アルブミン定性（尿） | E19: 49 | F19: 307675 | G19: 28367 | H19: 25524 | I19: 26059 | J19: 26407 | K19: 24381 | L19: 24423 | M19: 26916 | N19: 24246 | O19: 25507 | P19: 25064 | Q19: 23922 | R19: 26859
A20: D001 | B20: 尿中特殊物質定性定量検査 | C20: 160112110 | D20: ポルフォビリノゲン（尿） | E20: 186 | F20: 140 | G20: 15 | H20: 14 | I20: 13 | J20: - | K20: 12 | L20: - | M20: 14 | N20: 10 | O20: - | P20: 13 | Q20: 10 | R20: 13
A21: D001 | B21: 尿中特殊物質定性定量検査 | C21: 160112210 | D21: ウロポルフィリン（尿） | E21: 105 | F21: 661 | G21: 62 | H21: 53 | I21: 70 | J21: 65 | K21: 62 | L21: 56 | M21: 57 | N21: 36 | O21: 39 | P21: 47 | Q21: 49 | R21: 65
A22: D001 | B22: 尿中特殊物質定性定量検査 | C22: 160112310 | D22: コプロポルフィリン（尿） | E22: 131 | F22: 363 | G22: 27 | H22: 27 | I22: 38 | J22: 34 | K22: 37 | L22: 21 | M22: 34 | N22: 22 | O22: 23 | P22: 24 | Q22: 34 | R22: 42
A23: D001 | B23: 尿中特殊物質定性定量検査 | C23: 160134350 | D23: ポリアミン（尿） | E23: 115 | F23: - | G23: 0 | H23: 0 | I23: 0 | J23: 0 | K23: - | L23: 0 | M23: 0 | N23: 0 | O23: 0 | P23: - | Q23: 0 | R23: -
A24: D001 | B24: 尿中特殊物質定性定量検査 | C24: 160156710 | D24: ポルフィリン症スクリーニングテスト（尿） | E24: 17 | F24: - | G24: 0 | H24: 0 | I24: 0 | J24: - | K24: - | L24: - | M24: 0 | N24: 0 | O24: 0 | P24: 0 | Q24: 0 | R24: 0
A25: D001 | B25: 尿中特殊物質定性定量検査 | C25: 160157750 | D25: トランスフェリン（尿） | E25: 98 | F25: 5099 | G25: 447 | H25: 464 | I25: 413 | J25: 442 | K25: 446 | L25: 406 | M25: 432 | N25: 410 | O25: 382 | P25: 421 | Q25: 420 | R25: 416
A26: D001 | B26: 尿中特殊物質定性定量検査 | C26: 160169250 | D26: ４型コラーゲン（尿） | E26: 184 | F26: 2516 | G26: 225 | H26: 233 | I26: 199 | J26: 202 | K26: 174 | L26: 178 | M26: 258 | N26: 223 | O26: 185 | P26: 213 | Q26: 190 | R26: 236
A27: D001 | B27: 尿中特殊物質定性定量検査 | C27: 160176350 | D27: クレアチニン試験紙法（尿）（蛋白／クレアチニン比） | E27: 11 | F27: 315581 | G27: 27396 | H27: 26245 | I27: 26398 | J27: 27551 | K27: 25359 | L27: 25779 | M27: 27873 | N27: 26052 | O27: 26783 | P27: 25507 | Q27: 24240 | R27: 26398
A28: D001 | B28: 尿中特殊物質定性定量検査 | C28: 160189250 | D28: Ｌ型脂肪酸結合蛋白（Ｌ－ＦＡＢＰ）（尿） | E28: 210 | F28: 88871 | G28: 7712 | H28: 7394 | I28: 7176 | J28: 7822 | K28: 7337 | L28: 7549 | M28: 7751 | N28: 7332 | O28: 7599 | P28: 7157 | Q28: 6674 | R28: 7368
A29: D001 | B29: 尿中特殊物質定性定量検査 | C29: 160189950 | D29: 総ヨウ素（尿） | E29: 186 | F29: 256 | G29: 20 | H29: 10 | I29: 10 | J29: 16 | K29: - | L29: 13 | M29: 11 | N29: - | O29: - | P29: 35 | Q29: 54 | R29: 66
A30: D001 | B30: 尿中特殊物質定性定量検査 | C30: 160209650 | D30: 好中球ゼラチナーゼ結合性リポカリン（ＮＧＡＬ）（尿） | E30: 210 | F30: 1879 | G30: 171 | H30: 170 | I30: 159 | J30: 190 | K30: 176 | L30: 163 | M30: 158 | N30: 156 | O30: 132 | P30: 146 | Q30: 129 | R30: 129
A31: D001 | B31: 尿中特殊物質定性定量検査 | C31: 160210610 | D31: シュウ酸（尿） | E31: 200 | F31: 130 | G31: 12 | H31: 12 | I31: 13 | J31: 11 | K31: 11 | L31: 10 | M31: 16 | N31: 10 | O31: - | P31: 11 | Q31: 13 | R31: -
A32: D001 | B32: 尿中特殊物質定性定量検査 | C32: 160224650 | D32: トリプシノーゲン２（尿） | E32: 105 | F32: 1216 | G32: 101 | H32: 93 | I32: 128 | J32: 100 | K32: 94 | L32: 90 | M32: 98 | N32: 87 | O32: 94 | P32: 105 | Q32: 107 | R32: 119
A33: D001 | B33: 尿中特殊物質定性定量検査 | C33: 160237350 | D33: プロスタグランジンＥ主要代謝物（尿） | E33: 187 | F33: 956 | G33: 58 | H33: 66 | I33: 48 | J33: 68 | K33: 66 | L33: 93 | M33: 86 | N33: 91 | O33: 101 | P33: 89 | Q33: 100 | R33: 90
A34: D002 | B34: 尿沈渣（鏡検法） | C34: 160005010 | D34: 尿沈渣（鏡検法） | E34: 27 | F34: 18290110 | G34: 1578547 | H34: 1537629 | I34: 1518747 | J34: 1616299 | K34: 1492309 | L34: 1511716 | M34: 1614806 | N34: 1507504 | O34: 1532521 | P34: 1466036 | Q34: 1385836 | R34: 1528160
A35: D002-2 | B35: 尿沈渣（フローサイトメトリー法） | C35: 160159550 | D35: 尿沈渣（フローサイトメトリー法） | E35: 24 | F35: 3669858 | G35: 298843 | H35: 296095 | I35: 292234 | J35: 319341 | K35: 298651 | L35: 302120 | M35: 327632 | N35: 309010 | O35: 316157 | P35: 305184 | Q35: 287267 | R35: 317324
A36: D003 | B36: 糞便検査 | C36: 160005510 | D36: 糞便塗抹顕微鏡検査（虫卵、脂肪及び消化状況観察を含む。） | E36: 20 | F36: 7848 | G36: 611 | H36: 731 | I36: 758 | J36: 801 | K36: 660 | L36: 686 | M36: 646 | N36: 633 | O36: 526 | P36: 559 | Q36: 556 | R36: 681
A37: D003 | B37: 糞便検査 | C37: 160005710 | D37: 虫卵検出（集卵法）（糞便） | E37: 15 | F37: 2917 | G37: 228 | H37: 277 | I37: 303 | J37: 297 | K37: 246 | L37: 265 | M37: 277 | N37: 238 | O37: 212 | P37: 192 | Q37: 185 | R37: 197
A38: D003 | B38: 糞便検査 | C38: 160006310 | D38: 糞便中脂質 | E38: 25 | F38: 78 | G38: - | H38: - | I38: - | J38: - | K38: - | L38: 13 | M38: - | N38: 13 | O38: - | P38: - | Q38: - | R38: -
A39: D003 | B39: 糞便検査 | C39: 160006410 | D39: 虫体検出（糞便） | E39: 23 | F39: 1494 | G39: 133 | H39: 135 | I39: 180 | J39: 150 | K39: 104 | L39: 121 | M39: 124 | N39: 95 | O39: 107 | P39: 133 | Q39: 88 | R39: 124
A40: D003 | B40: 糞便検査 | C40: 160006510 | D40: 糞便中ヘモグロビン定性 | E40: 37 | F40: 1095364 | G40: 100799 | H40: 99496 | I40: 98046 | J40: 100791 | K40: 85994 | L40: 98996 | M40: 106285 | N40: 93065 | O40: 75438 | P40: 70572 | Q40: 76608 | R40: 89274
A41: D003 | B41: 糞便検査 | C41: 160006710 | D41: 虫卵培養（糞便） | E41: 40 | F41: 406 | G41: 33 | H41: 40 | I41: 45 | J41: 43 | K41: 26 | L41: 28 | M41: 24 | N41: 42 | O41: 31 | P41: 32 | Q41: 26 | R41: 36
A42: D003 | B42: 糞便検査 | C42: 160006810 | D42: 糞便中ヘモグロビン | E42: 41 | F42: 429405 | G42: 39529 | H42: 38909 | I42: 39702 | J42: 38884 | K42: 32104 | L42: 37733 | M42: 41641 | N42: 36240 | O42: 30221 | P42: 28929 | Q42: 29791 | R42: 35722
...

Sheet 外来（加算）
A1: 診療年月：2024年04月～2025年03月 D 検査 外来（加算） ※集計結果が10未満の場合は「‐」で表示（10未満の箇所が1箇所の場合は10以上の最小値を全て「‐」で表示）※集計対象期間内に名称や点数・金額等に変更がある場合、変更後の情報で表示
A3: 加算 | D3: 診療行為 コード | E3: 診療行為 | F3: 点数 | G3: % (加減算) | H3: 総計 (算定回数) | I3: 4月 | J3: 5月 | K3: 6月 | L3: 7月 | M3: 8月 | N3: 9月 | O3: 10月 | P3: 11月 | Q3: 12月 | R3: 1月 | S3: 2月 | T3: 3月
A5: 通則加算・注加算 | D5: 160000190 | E5: 検査逓減 | G5: -10 | H5: 3976992 | I5: 334188 | J5: 336332 | K5: 325610 | L5: 365589 | M5: 318794 | N5: 318102 | O5: 368169 | P5: 335366 | Q5: 317407 | R5: 311892 | S5: 298065 | T5: 347478
D6: 160000210 | E6: 時間外緊急院内検査加算 | F6: 200 | H6: 4485406 | I6: 238021 | J6: 290199 | K6: 252734 | L6: 369343 | M6: 356257 | N6: 289221 | O6: 231070 | P6: 259550 | Q6: 761703 | R6: 860300 | S6: 298267 | T6: 278741
D7: 160005170 | E7: 染色標本加算 | F7: 9 | H7: 3490260 | I7: 302010 | J7: 293298 | K7: 289384 | L7: 310885 | M7: 287732 | N7: 289595 | O7: 308597 | P7: 286178 | Q7: 294494 | R7: 278071 | S7: 261378 | T7: 288638
D8: 160008470 | E8: 特殊染色加算（末梢血液像（鏡検法）・オキシダーゼ染色） | F8: 37 | H8: 128 | I8: 16 | J8: - | K8: 13 | L8: 11 | M8: 15 | N8: 15 | O8: - | P8: - | Q8: 10 | R8: - | S8: - | T8: -
D9: 160008570 | E9: 特殊染色加算（末梢血液像（鏡検法）・ペルオキシダーゼ染色） | F9: 37 | H9: 287 | I9: 34 | J9: 28 | K9: 21 | L9: 23 | M9: 28 | N9: 32 | O9: 33 | P9: 24 | Q9: 20 | R9: 14 | S9: 12 | T9: 18
D10: 160008670 | E10: 特殊染色加算（末梢血液像（鏡検法）・アルカリホスファターゼ染色） | F10: 37 | H10: 4445 | I10: 380 | J10: 358 | K10: 377 | L10: 416 | M10: 338 | N10: 345 | O10: 444 | P10: 359 | Q10: 363 | R10: 337 | S10: 339 | T10: 389
D11: 160008770 | E11: 特殊染色加算（末梢血液像（鏡検法）・パス染色） | F11: 37 | H11: 35 | I11: - | J11: - | K11: - | L11: - | M11: - | N11: - | O11: - | P11: - | Q11: - | R11: - | S11: - | T11: 0
D12: 160008870 | E12: 特殊染色加算（末梢血液像（鏡検法）・鉄染色） | F12: 37 | H12: 60 | I12: - | J12: - | K12: - | L12: - | M12: - | N12: - | O12: - | P12: - | Q12: - | R12: - | S12: - | T12: -
D13: 160008970 | E13: 特殊染色加算（末梢血液像（鏡検法）・超生体染色） | F13: 37 | H13: - | I13: 0 | J13: 0 | K13: - | L13: - | M13: - | N13: - | O13: - | P13: 0 | Q13: - | R13: - | S13: - | T13: -
D14: 160009170 | E14: 特殊染色加算（末梢血液像（鏡検法）・脂肪染色） | F14: 37 | H14: - | I14: - | J14: - | K14: - | L14: - | M14: - | N14: - | O14: - | P14: - | Q14: - | R14: - | S14: - | T14: -
D15: 160009270 | E15: 特殊染色加算（末梢血液像（鏡検法）・エステラーゼ染色） | F15: 37 | H15: 292 | I15: 32 | J15: 30 | K15: 27 | L15: 31 | M15: 27 | N15: 23 | O15: 34 | P15: 30 | Q15: 46 | R15: - | S15: - | T15: -
D16: 160010570 | E16: 特殊染色加算（骨髄像・オキシダーゼ染色） | F16: 60 | H16: 943 | I16: 80 | J16: 85 | K16: 68 | L16: 76 | M16: 68 | N16: 91 | O16: 83 | P16: 91 | Q16: 76 | R16: 56 | S16: 67 | T16: 102
D17: 160010670 | E17: 特殊染色加算（骨髄像・ペルオキシダーゼ染色） | F17: 60 | H17: 33543 | I17: 2797 | J17: 2912 | K17: 2788 | L17: 3141 | M17: 2792 | N17: 2757 | O17: 3175 | P17: 2775 | Q17: 2605 | R17: 2639 | S17: 2433 | T17: 2729
D18: 160010770 | E18: 特殊染色加算（骨髄像・アルカリホスファターゼ染色） | F18: 60 | H18: 935 | I18: 66 | J18: 75 | K18: 62 | L18: 104 | M18: 81 | N18: 84 | O18: 102 | P18: 77 | Q18: 71 | R18: 65 | S18: 76 | T18: 72
D19: 160010870 | E19: 特殊染色加算（骨髄像・パス染色） | F19: 60 | H19: 6904 | I19: 574 | J19: 588 | K19: 577 | L19: 661 | M19: 556 | N19: 591 | O19: 652 | P19: 545 | Q19: 505 | R19: 549 | S19: 543 | T19: 563
D20: 160010970 | E20: 特殊染色加算（骨髄像・鉄染色） | F20: 60 | H20: 17667 | I20: 1449 | J20: 1498 | K20: 1535 | L20: 1678 | M20: 1508 | N20: 1458 | O20: 1716 | P20: 1439 | Q20: 1325 | R20: 1345 | S20: 1260 | T20: 1456
D21: 160011070 | E21: 特殊染色加算（骨髄像・超生体染色） | F21: 60 | H21: 593 | I21: 62 | J21: 58 | K21: 46 | L21: 48 | M21: 39 | N21: 49 | O21: 56 | P21: 52 | Q21: 54 | R21: 49 | S21: 42 | T21: 38
D22: 160011270 | E22: 特殊染色加算（骨髄像・脂肪染色） | F22: 60 | H22: 242 | I22: 14 | J22: 20 | K22: 21 | L22: 33 | M22: 21 | N22: 19 | O22: 19 | P22: 21 | Q22: 17 | R22: 17 | S22: 14 | T22: 26
D23: 160011370 | E23: 特殊染色加算（骨髄像・エステラーゼ染色） | F23: 60 | H23: 7444 | I23: 629 | J23: 632 | K23: 626 | L23: 704 | M23: 650 | N23: 597 | O23: 703 | P23: 588 | Q23: 554 | R23: 595 | S23: 562 | T23: 604
D24: 160058970 | E24: 嫌気性培養加算（細菌培養同定検査） | F24: 122 | H24: 758761 | I24: 64160 | J24: 71196 | K24: 71676 | L24: 66032 | M24: 57947 | N24: 54959 | O24: 61154 | P24: 57579 | Q24: 65679 | R24: 68386 | S24: 56734 | T24: 63259
D25: 160060870 | E25: 分染法加算（染色体検査） | F25: 397 | H25: 101760 | I25: 8485 | J25: 8679 | K25: 8555 | L25: 9264 | M25: 8405 | N25: 8353 | O25: 9413 | P25: 8472 | Q25: 7991 | R25: 8001 | S25: 7615 | T25: 8527
D26: 160062470 | E26: 負荷試験 | G26: 100 | H26: 23892 | I26: 2168 | J26: 1974 | K26: 1928 | L26: 2103 | M26: 1928 | N26: 1865 | O26: 2189 | P26: 2065 | Q26: 1978 | R26: 1916 | S26: 1696 | T26: 2082
D27: 160062570 | E27: 喘息に対する吸入誘発試験 | G27: 100 | H27: 2005 | I27: 160 | J27: 203 | K27: 171 | L27: 185 | M27: 166 | N27: 156 | O27: 160 | P27: 152 | Q27: 192 | R27: 191 | S27: 119 | T27: 150
D28: 160065270 | E28: 伝導機能検査加算（心臓カテーテル法） | F28: 400 | H28: 12 | I28: - | J28: - | K28: - | L28: 0 | M28: - | N28: - | O28: - | P28: 0 | Q28: 0 | R28: - | S28: - | T28: -
D29: 160065370 | E29: 期外刺激法加算（心臓カテーテル法） | F29: 800 | H29: - | I29: - | J29: - | K29: - | L29: - | M29: - | N29: - | O29: - | P29: - | Q29: - | R29: - | S29: - | T29: -
D30: 160065470 | E30: 冠動脈造影加算（心臓カテーテル法） | F30: 1400 | H30: 8655 | I30: 740 | J30: 686 | K30: 724 | L30: 736 | M30: 613 | N30: 692 | O30: 748 | P30: 742 | Q30: 749 | R30: 730 | S30: 702 | T30: 793
D31: 160065650 | E31: ヒス束心電図加算（心臓カテーテル法） | F31: 400 | H31: 12 | I31: - | J31: - | K31: - | L31: 0 | M31: - | N31: - | O31: - | P31: 0 | Q31: 0 | R31: - | S31: - | T31: -
D32: 160065750 | E32: 診断ペーシング加算（心臓カテーテル法） | F32: 400 | H32: 13 | I32: - | J32: - | K32: - | L32: 0 | M32: - | N32: - | O32: - | P32: 0 | Q32: 0 | R32: - | S32: - | T32: -
D33: 160067570 | E33: 心拍出量測定加算（体液量等測定） | F33: 1300 | H33: - | I33: - | J33: 0 | K33: - | L33: - | M33: 0 | N33: 0 | O33: 0 | P33: 0 | Q33: 0 | R33: - | S33: 0 | T33: 0
D34: 160071370 | E34: 負荷試験（運動又は薬剤の負荷） | G34: 100 | H34: 1011 | I34: 89 | J34: 90 | K34: 107 | L34: 85 | M34: 74 | N34: 87 | O34: 80 | P34: 63 | Q34: 101 | R34: 84 | S34: 66 | T34: 85
D35: 160072370 | E35: パルスドプラ法加算（超音波検査） | F35: 150 | H35: 3522590 | I35: 304892 | J35: 302455 | K35: 306507 | L35: 318093 | M35: 280363 | N35: 289042 | O35: 317526 | P35: 291936 | Q35: 280788 | R35: 266107 | S35: 264645 | T35: 300236
D36: 160073170 | E36: 負荷検査加算（サーモグラフィー検査）（記録に要する費用を含む。） | F36: 100 | H36: 489 | I36: 51 | J36: 48 | K36: 50 | L36: 29 | M36: 35 | N36: 35 | O36: 43 | P36: 42 | Q36: 40 | R36: 30 | S36: 37 | T36: 49
D37: 160075170 | E37: バルーン付肺動脈カテーテル挿入加算（観血的肺動脈圧測定） | F37: 1300 | H37: - | I37: - | J37: - | K37: - | L37: - | M37: - | N37: - | O37: - | P37: - | Q37: - | R37: - | S37: - | T37: -
D38: 160075570 | E38: 賦活検査加算（脳波検査） | F38: 250 | H38: 245827 | I38: 21187 | J38: 17486 | K38: 17914 | L38: 24088 | M38: 28708 | N38: 18477 | O38: 19412 | P38: 17802 | Q38: 19982 | R38: 18501 | S38: 17559 | T38: 24711
D39: 160083070 | E39: 負荷測定加算（精密眼圧測定） | F39: 55 | H39: 51688 | I39: 4813 | J39: 4502 | K39: 4601 | L39: 4401 | M39: 3669 | N39: 4191 | O39: 4506 | P39: 4128 | Q39: 4200 | R39: 3936 | S39: 4073 | T39: 4668
D40: 160092970 | E40: 気管支肺胞洗浄法検査同時加算（気管支ファイバースコピー） | F40: 200 | H40: 1291 | I40: 92 | J40: 120 | K40: 91 | L40: 117 | M40: 88 | N40: 114 | O40: 113 | P40: 118 | Q40: 106 | R40: 110 | S40: 106 | T40: 116
D41: 160093970 | E41: 胆管・膵管造影法加算（検査） | F41: 600 | H41: 869 | I41: 52 | J41: 69 | K41: 58 | L41: 57 | M41: 48 | N41: 84 | O41: 90 | P41: 97 | Q41: 78 | R41: 60 | S41: 84 | T41: 92
